-e 
===== ./file_watcher.err.log =====

[2025-05-16 17:45:05,017] INFO - [WATCHER] Watching directory: /app/static
[2025-05-16 17:45:05,017] DEBUG - [WATCHER] Initialized with watch dir: /app/static
[2025-05-16 17:45:05,017] INFO - [WATCHER] Scanning for pre-existing files...
[2025-05-16 17:45:05,017] DEBUG - [WATCHER] Found file: /app/static/profile/bun.lockb
[2025-05-16 17:45:05,018] DEBUG - [WATCHER] SHA256 for profile/bun.lockb: a3c575fd4a99dc9d1d74a4a7a31b979d577c15f379bc5cb0dd7e823586e98c23
[2025-05-16 17:45:05,018] INFO - [WATCHER] Detected new/changed file: profile/bun.lockb
[2025-05-16 17:45:05,018] INFO - [WATCHER] Sending file to: http://webtorrent:5002/seed
[2025-05-16 17:45:05,035] DEBUG - Starting new HTTP connection (1): webtorrent:5002
[2025-05-16 17:45:16,382] DEBUG - http://webtorrent:5002 "POST /seed HTTP/11" 200 133
[2025-05-16 17:45:16,398] INFO - [WATCHER] Seeding succeeded for profile/bun.lockb â†’ magnet:?xt=urn:btih:6002d80283b9303f529152f1a4a3d402b2bb3141&dn=bun.lockb&tr=wss%3A%2F%2Ftracker.openwebtorrent.com
[2025-05-16 17:45:16,398] INFO - [WATCHER] Committing magnet to blockchain...
[2025-05-16 17:45:16,399] DEBUG - Starting new HTTP connection (1): blockchain:5005
[2025-05-16 17:45:21,403] ERROR - [WATCHER] Blockchain commit error for profile/bun.lockb: HTTPConnectionPool(host='blockchain', port=5005): Max retries exceeded with url: /commit_magnet (Caused by NameResolutionError("<urllib3.connection.HTTPConnection object at 0x7e67c0a36810>: Failed to resolve 'blockchain' ([Errno -3] Try again)"))
Traceback (most recent call last):
  File "/venv/lib/python3.11/site-packages/urllib3/connection.py", line 196, in _new_conn
    sock = connection.create_connection(
           ^^^^^^^^^^^^^^^^^^^^^^^^^^^^^
  File "/venv/lib/python3.11/site-packages/urllib3/util/connection.py", line 60, in create_connection
    for res in socket.getaddrinfo(host, port, family, socket.SOCK_STREAM):
               ^^^^^^^^^^^^^^^^^^^^^^^^^^^^^^^^^^^^^^^^^^^^^^^^^^^^^^^^^^
  File "/usr/lib/python3.11/socket.py", line 974, in getaddrinfo
    for res in _socket.getaddrinfo(host, port, family, type, proto, flags):
               ^^^^^^^^^^^^^^^^^^^^^^^^^^^^^^^^^^^^^^^^^^^^^^^^^^^^^^^^^^^
socket.gaierror: [Errno -3] Try again

The above exception was the direct cause of the following exception:

Traceback (most recent call last):
  File "/venv/lib/python3.11/site-packages/urllib3/connectionpool.py", line 789, in urlopen
    response = self._make_request(
               ^^^^^^^^^^^^^^^^^^^
  File "/venv/lib/python3.11/site-packages/urllib3/connectionpool.py", line 495, in _make_request
    conn.request(
  File "/venv/lib/python3.11/site-packages/urllib3/connection.py", line 398, in request
    self.endheaders()
  File "/usr/lib/python3.11/http/client.py", line 1298, in endheaders
    self._send_output(message_body, encode_chunked=encode_chunked)
  File "/usr/lib/python3.11/http/client.py", line 1058, in _send_output
    self.send(msg)
  File "/usr/lib/python3.11/http/client.py", line 996, in send
    self.connect()
  File "/venv/lib/python3.11/site-packages/urllib3/connection.py", line 236, in connect
    self.sock = self._new_conn()
                ^^^^^^^^^^^^^^^^
  File "/venv/lib/python3.11/site-packages/urllib3/connection.py", line 203, in _new_conn
    raise NameResolutionError(self.host, self, e) from e
urllib3.exceptions.NameResolutionError: <urllib3.connection.HTTPConnection object at 0x7e67c0a36810>: Failed to resolve 'blockchain' ([Errno -3] Try again)

The above exception was the direct cause of the following exception:

Traceback (most recent call last):
  File "/venv/lib/python3.11/site-packages/requests/adapters.py", line 667, in send
    resp = conn.urlopen(
           ^^^^^^^^^^^^^
  File "/venv/lib/python3.11/site-packages/urllib3/connectionpool.py", line 843, in urlopen
    retries = retries.increment(
              ^^^^^^^^^^^^^^^^^^
  File "/venv/lib/python3.11/site-packages/urllib3/util/retry.py", line 519, in increment
    raise MaxRetryError(_pool, url, reason) from reason  # type: ignore[arg-type]
    ^^^^^^^^^^^^^^^^^^^^^^^^^^^^^^^^^^^^^^^^^^^^^^^^^^^
urllib3.exceptions.MaxRetryError: HTTPConnectionPool(host='blockchain', port=5005): Max retries exceeded with url: /commit_magnet (Caused by NameResolutionError("<urllib3.connection.HTTPConnection object at 0x7e67c0a36810>: Failed to resolve 'blockchain' ([Errno -3] Try again)"))

During handling of the above exception, another exception occurred:

Traceback (most recent call last):
  File "/app/services/file_watcher.py", line 104, in _commit_magnet_url
    resp = requests.post(f"{Config.BLOCKCHAIN_URI}/commit_magnet", json=payload)
           ^^^^^^^^^^^^^^^^^^^^^^^^^^^^^^^^^^^^^^^^^^^^^^^^^^^^^^^^^^^^^^^^^^^^^
  File "/venv/lib/python3.11/site-packages/requests/api.py", line 115, in post
    return request("post", url, data=data, json=json, **kwargs)
           ^^^^^^^^^^^^^^^^^^^^^^^^^^^^^^^^^^^^^^^^^^^^^^^^^^^^
  File "/venv/lib/python3.11/site-packages/requests/api.py", line 59, in request
    return session.request(method=method, url=url, **kwargs)
           ^^^^^^^^^^^^^^^^^^^^^^^^^^^^^^^^^^^^^^^^^^^^^^^^^
  File "/venv/lib/python3.11/site-packages/requests/sessions.py", line 589, in request
    resp = self.send(prep, **send_kwargs)
           ^^^^^^^^^^^^^^^^^^^^^^^^^^^^^^
  File "/venv/lib/python3.11/site-packages/requests/sessions.py", line 703, in send
    r = adapter.send(request, **kwargs)
        ^^^^^^^^^^^^^^^^^^^^^^^^^^^^^^^
  File "/venv/lib/python3.11/site-packages/requests/adapters.py", line 700, in send
    raise ConnectionError(e, request=request)
requests.exceptions.ConnectionError: HTTPConnectionPool(host='blockchain', port=5005): Max retries exceeded with url: /commit_magnet (Caused by NameResolutionError("<urllib3.connection.HTTPConnection object at 0x7e67c0a36810>: Failed to resolve 'blockchain' ([Errno -3] Try again)"))
[2025-05-16 17:45:21,439] DEBUG - [WATCHER] Found file: /app/static/profile/tsconfig.node.json
[2025-05-16 17:45:21,441] DEBUG - [WATCHER] SHA256 for profile/tsconfig.node.json: a96b9ba5e40d95b92adf56431fdf9cbe25b5c2557621f0666615bff6889dfc50
[2025-05-16 17:45:21,441] INFO - [WATCHER] Detected new/changed file: profile/tsconfig.node.json
[2025-05-16 17:45:21,441] INFO - [WATCHER] Sending file to: http://webtorrent:5002/seed
[2025-05-16 17:45:21,442] DEBUG - Starting new HTTP connection (1): webtorrent:5002
-e 
===== ./webtorrent.log =====

[2025-05-16 17:45:03,647] INFO in _internal: [31m[1mWARNING: This is a development server. Do not use it in a production deployment. Use a production WSGI server instead.[0m
 * Running on all addresses (0.0.0.0)
 * Running on http://127.0.0.1:5002
 * Running on http://172.19.0.4:5002
[2025-05-16 17:45:03,647] INFO in _internal: [33mPress CTRL+C to quit[0m
[2025-05-16 17:45:05,040] INFO in routes: Received request to seed a file.
[2025-05-16 17:45:05,046] INFO in routes: File /app/uploads/bun.lockb already exists on disk.
[2025-05-16 17:45:05,046] INFO in routes: Seeding file /app/uploads/bun.lockb...
[2025-05-16 17:45:05,050] DEBUG in monitor: [stream_output] Started for 0x000000000000000000000000000000000000dead, snapshot 0
[2025-05-16 17:45:07,079] INFO in monitor: [stream_output] Raw line: 
[2025-05-16 17:45:16,354] INFO in monitor: [stream_output] Raw line: Seeding: bun.lockb
[2025-05-16 17:45:16,354] INFO in monitor: [stream_output] Raw line: Magnet: magnet:?xt=urn:btih:6002d80283b9303f529152f1a4a3d402b2bb3141&dn=bun.lockb&tr=wss%3A%2F%2Ftracker.openwebtorrent.com
[2025-05-16 17:45:16,354] INFO in monitor: [stream_output] Found magnet URL: magnet:?xt=urn:btih:6002d80283b9303f529152f1a4a3d402b2bb3141&dn=bun.lockb&tr=wss%3A%2F%2Ftracker.openwebtorrent.com
[2025-05-16 17:45:16,354] DEBUG in monitor: Storing magnet URL for 0x000000000000000000000000000000000000dead, snapshot 0
[2025-05-16 17:45:16,354] INFO in monitor: Sending POST request to store magnet URL for 0x000000000000000000000000000000000000dead, snapshot 0
[2025-05-16 17:45:16,370] INFO in monitor: Successfully stored magnet URL for 0x000000000000000000000000000000000000dead, snapshot 0
[2025-05-16 17:45:16,371] DEBUG in monitor: [stream_output] Completed for 0x000000000000000000000000000000000000dead: magnet:?xt=urn:btih:6002d80283b9303f529152f1a4a3d402b2bb3141&dn=bun.lockb&tr=wss%3A%2F%2Ftracker.openwebtorrent.com
[2025-05-16 17:45:16,373] INFO in _internal: 172.19.0.7 - - [16/May/2025 17:45:16] "POST /seed HTTP/1.1" 200 -
[2025-05-16 17:45:21,450] INFO in routes: Received request to seed a file.
[2025-05-16 17:45:21,453] INFO in routes: File /app/uploads/tsconfig.node.json already exists on disk.
[2025-05-16 17:45:21,453] INFO in routes: Seeding file /app/uploads/tsconfig.node.json...
[2025-05-16 17:45:21,456] DEBUG in monitor: [stream_output] Started for 0x000000000000000000000000000000000000dead, snapshot 0
-e 
===== ./file_watcher.log =====

[2025-05-16 17:45:05,017] INFO - [WATCHER] Watching directory: /app/static
[2025-05-16 17:45:05,017] DEBUG - [WATCHER] Initialized with watch dir: /app/static
[2025-05-16 17:45:05,017] INFO - [WATCHER] Scanning for pre-existing files...
[2025-05-16 17:45:05,017] DEBUG - [WATCHER] Found file: /app/static/profile/bun.lockb
[2025-05-16 17:45:05,018] DEBUG - [WATCHER] SHA256 for profile/bun.lockb: a3c575fd4a99dc9d1d74a4a7a31b979d577c15f379bc5cb0dd7e823586e98c23
[2025-05-16 17:45:05,018] INFO - [WATCHER] Detected new/changed file: profile/bun.lockb
[2025-05-16 17:45:05,018] INFO - [WATCHER] Sending file to: http://webtorrent:5002/seed
[2025-05-16 17:45:05,035] DEBUG - Starting new HTTP connection (1): webtorrent:5002
[2025-05-16 17:45:16,382] DEBUG - http://webtorrent:5002 "POST /seed HTTP/11" 200 133
[2025-05-16 17:45:16,398] INFO - [WATCHER] Seeding succeeded for profile/bun.lockb â†’ magnet:?xt=urn:btih:6002d80283b9303f529152f1a4a3d402b2bb3141&dn=bun.lockb&tr=wss%3A%2F%2Ftracker.openwebtorrent.com
[2025-05-16 17:45:16,398] INFO - [WATCHER] Committing magnet to blockchain...
[2025-05-16 17:45:16,399] DEBUG - Starting new HTTP connection (1): blockchain:5005
[2025-05-16 17:45:21,403] ERROR - [WATCHER] Blockchain commit error for profile/bun.lockb: HTTPConnectionPool(host='blockchain', port=5005): Max retries exceeded with url: /commit_magnet (Caused by NameResolutionError("<urllib3.connection.HTTPConnection object at 0x7e67c0a36810>: Failed to resolve 'blockchain' ([Errno -3] Try again)"))
Traceback (most recent call last):
  File "/venv/lib/python3.11/site-packages/urllib3/connection.py", line 196, in _new_conn
    sock = connection.create_connection(
           ^^^^^^^^^^^^^^^^^^^^^^^^^^^^^
  File "/venv/lib/python3.11/site-packages/urllib3/util/connection.py", line 60, in create_connection
    for res in socket.getaddrinfo(host, port, family, socket.SOCK_STREAM):
               ^^^^^^^^^^^^^^^^^^^^^^^^^^^^^^^^^^^^^^^^^^^^^^^^^^^^^^^^^^
  File "/usr/lib/python3.11/socket.py", line 974, in getaddrinfo
    for res in _socket.getaddrinfo(host, port, family, type, proto, flags):
               ^^^^^^^^^^^^^^^^^^^^^^^^^^^^^^^^^^^^^^^^^^^^^^^^^^^^^^^^^^^
socket.gaierror: [Errno -3] Try again

The above exception was the direct cause of the following exception:

Traceback (most recent call last):
  File "/venv/lib/python3.11/site-packages/urllib3/connectionpool.py", line 789, in urlopen
    response = self._make_request(
               ^^^^^^^^^^^^^^^^^^^
  File "/venv/lib/python3.11/site-packages/urllib3/connectionpool.py", line 495, in _make_request
    conn.request(
  File "/venv/lib/python3.11/site-packages/urllib3/connection.py", line 398, in request
    self.endheaders()
  File "/usr/lib/python3.11/http/client.py", line 1298, in endheaders
    self._send_output(message_body, encode_chunked=encode_chunked)
  File "/usr/lib/python3.11/http/client.py", line 1058, in _send_output
    self.send(msg)
  File "/usr/lib/python3.11/http/client.py", line 996, in send
    self.connect()
  File "/venv/lib/python3.11/site-packages/urllib3/connection.py", line 236, in connect
    self.sock = self._new_conn()
                ^^^^^^^^^^^^^^^^
  File "/venv/lib/python3.11/site-packages/urllib3/connection.py", line 203, in _new_conn
    raise NameResolutionError(self.host, self, e) from e
urllib3.exceptions.NameResolutionError: <urllib3.connection.HTTPConnection object at 0x7e67c0a36810>: Failed to resolve 'blockchain' ([Errno -3] Try again)

The above exception was the direct cause of the following exception:

Traceback (most recent call last):
  File "/venv/lib/python3.11/site-packages/requests/adapters.py", line 667, in send
    resp = conn.urlopen(
           ^^^^^^^^^^^^^
  File "/venv/lib/python3.11/site-packages/urllib3/connectionpool.py", line 843, in urlopen
    retries = retries.increment(
              ^^^^^^^^^^^^^^^^^^
  File "/venv/lib/python3.11/site-packages/urllib3/util/retry.py", line 519, in increment
    raise MaxRetryError(_pool, url, reason) from reason  # type: ignore[arg-type]
    ^^^^^^^^^^^^^^^^^^^^^^^^^^^^^^^^^^^^^^^^^^^^^^^^^^^
urllib3.exceptions.MaxRetryError: HTTPConnectionPool(host='blockchain', port=5005): Max retries exceeded with url: /commit_magnet (Caused by NameResolutionError("<urllib3.connection.HTTPConnection object at 0x7e67c0a36810>: Failed to resolve 'blockchain' ([Errno -3] Try again)"))

During handling of the above exception, another exception occurred:

Traceback (most recent call last):
  File "/app/services/file_watcher.py", line 104, in _commit_magnet_url
    resp = requests.post(f"{Config.BLOCKCHAIN_URI}/commit_magnet", json=payload)
           ^^^^^^^^^^^^^^^^^^^^^^^^^^^^^^^^^^^^^^^^^^^^^^^^^^^^^^^^^^^^^^^^^^^^^
  File "/venv/lib/python3.11/site-packages/requests/api.py", line 115, in post
    return request("post", url, data=data, json=json, **kwargs)
           ^^^^^^^^^^^^^^^^^^^^^^^^^^^^^^^^^^^^^^^^^^^^^^^^^^^^
  File "/venv/lib/python3.11/site-packages/requests/api.py", line 59, in request
    return session.request(method=method, url=url, **kwargs)
           ^^^^^^^^^^^^^^^^^^^^^^^^^^^^^^^^^^^^^^^^^^^^^^^^^
  File "/venv/lib/python3.11/site-packages/requests/sessions.py", line 589, in request
    resp = self.send(prep, **send_kwargs)
           ^^^^^^^^^^^^^^^^^^^^^^^^^^^^^^
  File "/venv/lib/python3.11/site-packages/requests/sessions.py", line 703, in send
    r = adapter.send(request, **kwargs)
        ^^^^^^^^^^^^^^^^^^^^^^^^^^^^^^^
  File "/venv/lib/python3.11/site-packages/requests/adapters.py", line 700, in send
    raise ConnectionError(e, request=request)
requests.exceptions.ConnectionError: HTTPConnectionPool(host='blockchain', port=5005): Max retries exceeded with url: /commit_magnet (Caused by NameResolutionError("<urllib3.connection.HTTPConnection object at 0x7e67c0a36810>: Failed to resolve 'blockchain' ([Errno -3] Try again)"))
[2025-05-16 17:45:21,439] DEBUG - [WATCHER] Found file: /app/static/profile/tsconfig.node.json
[2025-05-16 17:45:21,441] DEBUG - [WATCHER] SHA256 for profile/tsconfig.node.json: a96b9ba5e40d95b92adf56431fdf9cbe25b5c2557621f0666615bff6889dfc50
[2025-05-16 17:45:21,441] INFO - [WATCHER] Detected new/changed file: profile/tsconfig.node.json
[2025-05-16 17:45:21,441] INFO - [WATCHER] Sending file to: http://webtorrent:5002/seed
[2025-05-16 17:45:21,442] DEBUG - Starting new HTTP connection (1): webtorrent:5002
-e 
===== ./verifier.err.log =====

/app/verifier/node_modules/ethers/lib.commonjs/utils/errors.js:149
        throw makeError(message, code, info);
        ^

TypeError: invalid private key (argument="privateKey", value="[ REDACTED ]", code=INVALID_ARGUMENT, version=6.14.1)
    at makeError (/app/verifier/node_modules/ethers/lib.commonjs/utils/errors.js:122:21)
    at assert (/app/verifier/node_modules/ethers/lib.commonjs/utils/errors.js:149:15)
    at assertArgument (/app/verifier/node_modules/ethers/lib.commonjs/utils/errors.js:161:5)
    at new BaseWallet (/app/verifier/node_modules/ethers/lib.commonjs/wallet/base-wallet.js:35:39)
    at new Wallet (/app/verifier/node_modules/ethers/lib.commonjs/wallet/wallet.js:34:9)
    at Object.<anonymous> (/app/verifier/verifier.js:16:16)
    at Module._compile (node:internal/modules/cjs/loader:1358:14)
    at Module._extensions..js (node:internal/modules/cjs/loader:1416:10)
    at Module.load (node:internal/modules/cjs/loader:1208:32)
    at Module._load (node:internal/modules/cjs/loader:1024:12) {
  code: 'INVALID_ARGUMENT',
  argument: 'privateKey',
  value: '[ REDACTED ]',
  shortMessage: 'invalid private key'
}

Node.js v20.15.1
/app/verifier/node_modules/ethers/lib.commonjs/utils/errors.js:149
        throw makeError(message, code, info);
        ^

TypeError: invalid private key (argument="privateKey", value="[ REDACTED ]", code=INVALID_ARGUMENT, version=6.14.1)
    at makeError (/app/verifier/node_modules/ethers/lib.commonjs/utils/errors.js:122:21)
    at assert (/app/verifier/node_modules/ethers/lib.commonjs/utils/errors.js:149:15)
    at assertArgument (/app/verifier/node_modules/ethers/lib.commonjs/utils/errors.js:161:5)
    at new BaseWallet (/app/verifier/node_modules/ethers/lib.commonjs/wallet/base-wallet.js:35:39)
    at new Wallet (/app/verifier/node_modules/ethers/lib.commonjs/wallet/wallet.js:34:9)
    at Object.<anonymous> (/app/verifier/verifier.js:16:16)
    at Module._compile (node:internal/modules/cjs/loader:1358:14)
    at Module._extensions..js (node:internal/modules/cjs/loader:1416:10)
    at Module.load (node:internal/modules/cjs/loader:1208:32)
    at Module._load (node:internal/modules/cjs/loader:1024:12) {
  code: 'INVALID_ARGUMENT',
  argument: 'privateKey',
  value: '[ REDACTED ]',
  shortMessage: 'invalid private key'
}

Node.js v20.15.1
/app/verifier/node_modules/ethers/lib.commonjs/utils/errors.js:149
        throw makeError(message, code, info);
        ^

TypeError: invalid private key (argument="privateKey", value="[ REDACTED ]", code=INVALID_ARGUMENT, version=6.14.1)
    at makeError (/app/verifier/node_modules/ethers/lib.commonjs/utils/errors.js:122:21)
    at assert (/app/verifier/node_modules/ethers/lib.commonjs/utils/errors.js:149:15)
    at assertArgument (/app/verifier/node_modules/ethers/lib.commonjs/utils/errors.js:161:5)
    at new BaseWallet (/app/verifier/node_modules/ethers/lib.commonjs/wallet/base-wallet.js:35:39)
    at new Wallet (/app/verifier/node_modules/ethers/lib.commonjs/wallet/wallet.js:34:9)
    at Object.<anonymous> (/app/verifier/verifier.js:16:16)
    at Module._compile (node:internal/modules/cjs/loader:1358:14)
    at Module._extensions..js (node:internal/modules/cjs/loader:1416:10)
    at Module.load (node:internal/modules/cjs/loader:1208:32)
    at Module._load (node:internal/modules/cjs/loader:1024:12) {
  code: 'INVALID_ARGUMENT',
  argument: 'privateKey',
  value: '[ REDACTED ]',
  shortMessage: 'invalid private key'
}

Node.js v20.15.1
/app/verifier/node_modules/ethers/lib.commonjs/utils/errors.js:149
        throw makeError(message, code, info);
        ^

TypeError: invalid private key (argument="privateKey", value="[ REDACTED ]", code=INVALID_ARGUMENT, version=6.14.1)
    at makeError (/app/verifier/node_modules/ethers/lib.commonjs/utils/errors.js:122:21)
    at assert (/app/verifier/node_modules/ethers/lib.commonjs/utils/errors.js:149:15)
    at assertArgument (/app/verifier/node_modules/ethers/lib.commonjs/utils/errors.js:161:5)
    at new BaseWallet (/app/verifier/node_modules/ethers/lib.commonjs/wallet/base-wallet.js:35:39)
    at new Wallet (/app/verifier/node_modules/ethers/lib.commonjs/wallet/wallet.js:34:9)
    at Object.<anonymous> (/app/verifier/verifier.js:16:16)
    at Module._compile (node:internal/modules/cjs/loader:1358:14)
    at Module._extensions..js (node:internal/modules/cjs/loader:1416:10)
    at Module.load (node:internal/modules/cjs/loader:1208:32)
    at Module._load (node:internal/modules/cjs/loader:1024:12) {
  code: 'INVALID_ARGUMENT',
  argument: 'privateKey',
  value: '[ REDACTED ]',
  shortMessage: 'invalid private key'
}

Node.js v20.15.1
/app/verifier/node_modules/ethers/lib.commonjs/utils/errors.js:149
        throw makeError(message, code, info);
        ^

TypeError: invalid private key (argument="privateKey", value="[ REDACTED ]", code=INVALID_ARGUMENT, version=6.14.1)
    at makeError (/app/verifier/node_modules/ethers/lib.commonjs/utils/errors.js:122:21)
    at assert (/app/verifier/node_modules/ethers/lib.commonjs/utils/errors.js:149:15)
    at assertArgument (/app/verifier/node_modules/ethers/lib.commonjs/utils/errors.js:161:5)
    at new BaseWallet (/app/verifier/node_modules/ethers/lib.commonjs/wallet/base-wallet.js:35:39)
    at new Wallet (/app/verifier/node_modules/ethers/lib.commonjs/wallet/wallet.js:34:9)
    at Object.<anonymous> (/app/verifier/verifier.js:16:16)
    at Module._compile (node:internal/modules/cjs/loader:1358:14)
    at Module._extensions..js (node:internal/modules/cjs/loader:1416:10)
    at Module.load (node:internal/modules/cjs/loader:1208:32)
    at Module._load (node:internal/modules/cjs/loader:1024:12) {
  code: 'INVALID_ARGUMENT',
  argument: 'privateKey',
  value: '[ REDACTED ]',
  shortMessage: 'invalid private key'
}

Node.js v20.15.1
/app/verifier/node_modules/ethers/lib.commonjs/utils/errors.js:149
        throw makeError(message, code, info);
        ^

TypeError: invalid private key (argument="privateKey", value="[ REDACTED ]", code=INVALID_ARGUMENT, version=6.14.1)
    at makeError (/app/verifier/node_modules/ethers/lib.commonjs/utils/errors.js:122:21)
    at assert (/app/verifier/node_modules/ethers/lib.commonjs/utils/errors.js:149:15)
    at assertArgument (/app/verifier/node_modules/ethers/lib.commonjs/utils/errors.js:161:5)
    at new BaseWallet (/app/verifier/node_modules/ethers/lib.commonjs/wallet/base-wallet.js:35:39)
    at new Wallet (/app/verifier/node_modules/ethers/lib.commonjs/wallet/wallet.js:34:9)
    at Object.<anonymous> (/app/verifier/verifier.js:16:16)
    at Module._compile (node:internal/modules/cjs/loader:1358:14)
    at Module._extensions..js (node:internal/modules/cjs/loader:1416:10)
    at Module.load (node:internal/modules/cjs/loader:1208:32)
    at Module._load (node:internal/modules/cjs/loader:1024:12) {
  code: 'INVALID_ARGUMENT',
  argument: 'privateKey',
  value: '[ REDACTED ]',
  shortMessage: 'invalid private key'
}

Node.js v20.15.1
/app/verifier/node_modules/ethers/lib.commonjs/utils/errors.js:149
        throw makeError(message, code, info);
        ^

TypeError: invalid private key (argument="privateKey", value="[ REDACTED ]", code=INVALID_ARGUMENT, version=6.14.1)
    at makeError (/app/verifier/node_modules/ethers/lib.commonjs/utils/errors.js:122:21)
    at assert (/app/verifier/node_modules/ethers/lib.commonjs/utils/errors.js:149:15)
    at assertArgument (/app/verifier/node_modules/ethers/lib.commonjs/utils/errors.js:161:5)
    at new BaseWallet (/app/verifier/node_modules/ethers/lib.commonjs/wallet/base-wallet.js:35:39)
    at new Wallet (/app/verifier/node_modules/ethers/lib.commonjs/wallet/wallet.js:34:9)
    at Object.<anonymous> (/app/verifier/verifier.js:16:16)
    at Module._compile (node:internal/modules/cjs/loader:1358:14)
    at Module._extensions..js (node:internal/modules/cjs/loader:1416:10)
    at Module.load (node:internal/modules/cjs/loader:1208:32)
    at Module._load (node:internal/modules/cjs/loader:1024:12) {
  code: 'INVALID_ARGUMENT',
  argument: 'privateKey',
  value: '[ REDACTED ]',
  shortMessage: 'invalid private key'
}

Node.js v20.15.1
/app/verifier/node_modules/ethers/lib.commonjs/utils/errors.js:149
        throw makeError(message, code, info);
        ^

TypeError: invalid private key (argument="privateKey", value="[ REDACTED ]", code=INVALID_ARGUMENT, version=6.14.1)
    at makeError (/app/verifier/node_modules/ethers/lib.commonjs/utils/errors.js:122:21)
    at assert (/app/verifier/node_modules/ethers/lib.commonjs/utils/errors.js:149:15)
    at assertArgument (/app/verifier/node_modules/ethers/lib.commonjs/utils/errors.js:161:5)
    at new BaseWallet (/app/verifier/node_modules/ethers/lib.commonjs/wallet/base-wallet.js:35:39)
    at new Wallet (/app/verifier/node_modules/ethers/lib.commonjs/wallet/wallet.js:34:9)
    at Object.<anonymous> (/app/verifier/verifier.js:16:16)
    at Module._compile (node:internal/modules/cjs/loader:1358:14)
    at Module._extensions..js (node:internal/modules/cjs/loader:1416:10)
    at Module.load (node:internal/modules/cjs/loader:1208:32)
    at Module._load (node:internal/modules/cjs/loader:1024:12) {
  code: 'INVALID_ARGUMENT',
  argument: 'privateKey',
  value: '[ REDACTED ]',
  shortMessage: 'invalid private key'
}

Node.js v20.15.1
/app/verifier/node_modules/ethers/lib.commonjs/utils/errors.js:149
        throw makeError(message, code, info);
        ^

TypeError: invalid private key (argument="privateKey", value="[ REDACTED ]", code=INVALID_ARGUMENT, version=6.14.1)
    at makeError (/app/verifier/node_modules/ethers/lib.commonjs/utils/errors.js:122:21)
    at assert (/app/verifier/node_modules/ethers/lib.commonjs/utils/errors.js:149:15)
    at assertArgument (/app/verifier/node_modules/ethers/lib.commonjs/utils/errors.js:161:5)
    at new BaseWallet (/app/verifier/node_modules/ethers/lib.commonjs/wallet/base-wallet.js:35:39)
    at new Wallet (/app/verifier/node_modules/ethers/lib.commonjs/wallet/wallet.js:34:9)
    at Object.<anonymous> (/app/verifier/verifier.js:16:16)
    at Module._compile (node:internal/modules/cjs/loader:1358:14)
    at Module._extensions..js (node:internal/modules/cjs/loader:1416:10)
    at Module.load (node:internal/modules/cjs/loader:1208:32)
    at Module._load (node:internal/modules/cjs/loader:1024:12) {
  code: 'INVALID_ARGUMENT',
  argument: 'privateKey',
  value: '[ REDACTED ]',
  shortMessage: 'invalid private key'
}

Node.js v20.15.1
-e 
===== ./gunicorn.err.log =====

[2025-05-16 17:45:04 +0000] [17] [INFO] Starting gunicorn 23.0.0
[2025-05-16 17:45:04 +0000] [17] [INFO] Listening at: https://0.0.0.0:5000 (17)
[2025-05-16 17:45:04 +0000] [17] [INFO] Using worker: gevent
[2025-05-16 17:45:04 +0000] [26] [INFO] Booting worker with pid: 26
[2025-05-16 17:45:05 +0000] [27] [INFO] Booting worker with pid: 27
[2025-05-16 17:45:05 +0000] [28] [INFO] Booting worker with pid: 28
[2025-05-16 17:45:05 +0000] [29] [INFO] Booting worker with pid: 29
[2025-05-16 17:45:05 +0000] [30] [INFO] Booting worker with pid: 30
[2025-05-16 17:45:05 +0000] [31] [INFO] Booting worker with pid: 31
[2025-05-16 17:45:05 +0000] [33] [INFO] Booting worker with pid: 33
[2025-05-16 17:45:05 +0000] [34] [INFO] Booting worker with pid: 34
[2025-05-16 17:45:05 +0000] [35] [INFO] Booting worker with pid: 35
[2025-05-16 17:45:08 +0000] [28] [ERROR] Exception in worker process
Traceback (most recent call last):
  File "/venv/lib/python3.11/site-packages/gunicorn/arbiter.py", line 608, in spawn_worker
    worker.init_process()
  File "/venv/lib/python3.11/site-packages/gunicorn/workers/ggevent.py", line 146, in init_process
    super().init_process()
  File "/venv/lib/python3.11/site-packages/gunicorn/workers/base.py", line 135, in init_process
    self.load_wsgi()
  File "/venv/lib/python3.11/site-packages/gunicorn/workers/base.py", line 147, in load_wsgi
    self.wsgi = self.app.wsgi()
                ^^^^^^^^^^^^^^^
  File "/venv/lib/python3.11/site-packages/gunicorn/app/base.py", line 66, in wsgi
    self.callable = self.load()
                    ^^^^^^^^^^^
  File "/venv/lib/python3.11/site-packages/gunicorn/app/wsgiapp.py", line 57, in load
    return self.load_wsgiapp()
           ^^^^^^^^^^^^^^^^^^^
  File "/venv/lib/python3.11/site-packages/gunicorn/app/wsgiapp.py", line 47, in load_wsgiapp
    return util.import_app(self.app_uri)
           ^^^^^^^^^^^^^^^^^^^^^^^^^^^^^
  File "/venv/lib/python3.11/site-packages/gunicorn/util.py", line 370, in import_app
    mod = importlib.import_module(module)
          ^^^^^^^^^^^^^^^^^^^^^^^^^^^^^^^
  File "/usr/lib/python3.11/importlib/__init__.py", line 126, in import_module
    return _bootstrap._gcd_import(name[level:], package, level)
           ^^^^^^^^^^^^^^^^^^^^^^^^^^^^^^^^^^^^^^^^^^^^^^^^^^^^
  File "<frozen importlib._bootstrap>", line 1204, in _gcd_import
  File "<frozen importlib._bootstrap>", line 1176, in _find_and_load
  File "<frozen importlib._bootstrap>", line 1147, in _find_and_load_unlocked
  File "<frozen importlib._bootstrap>", line 690, in _load_unlocked
  File "<frozen importlib._bootstrap_external>", line 940, in exec_module
  File "<frozen importlib._bootstrap>", line 241, in _call_with_frames_removed
  File "/app/driver.py", line 5, in <module>
    from api import create_app
  File "/app/api/__init__.py", line 7, in <module>
    from api.routes.verify_proxy import verify_bp
ModuleNotFoundError: No module named 'api.routes.verify_proxy'; 'api.routes' is not a package
[2025-05-16 17:45:08 +0000] [28] [INFO] Worker exiting (pid: 28)
[2025-05-16 17:45:08 +0000] [27] [ERROR] Exception in worker process
Traceback (most recent call last):
  File "/venv/lib/python3.11/site-packages/gunicorn/arbiter.py", line 608, in spawn_worker
    worker.init_process()
  File "/venv/lib/python3.11/site-packages/gunicorn/workers/ggevent.py", line 146, in init_process
    super().init_process()
  File "/venv/lib/python3.11/site-packages/gunicorn/workers/base.py", line 135, in init_process
    self.load_wsgi()
  File "/venv/lib/python3.11/site-packages/gunicorn/workers/base.py", line 147, in load_wsgi
    self.wsgi = self.app.wsgi()
                ^^^^^^^^^^^^^^^
  File "/venv/lib/python3.11/site-packages/gunicorn/app/base.py", line 66, in wsgi
    self.callable = self.load()
                    ^^^^^^^^^^^
  File "/venv/lib/python3.11/site-packages/gunicorn/app/wsgiapp.py", line 57, in load
    return self.load_wsgiapp()
           ^^^^^^^^^^^^^^^^^^^
  File "/venv/lib/python3.11/site-packages/gunicorn/app/wsgiapp.py", line 47, in load_wsgiapp
    return util.import_app(self.app_uri)
           ^^^^^^^^^^^^^^^^^^^^^^^^^^^^^
  File "/venv/lib/python3.11/site-packages/gunicorn/util.py", line 370, in import_app
    mod = importlib.import_module(module)
          ^^^^^^^^^^^^^^^^^^^^^^^^^^^^^^^
  File "/usr/lib/python3.11/importlib/__init__.py", line 126, in import_module
    return _bootstrap._gcd_import(name[level:], package, level)
           ^^^^^^^^^^^^^^^^^^^^^^^^^^^^^^^^^^^^^^^^^^^^^^^^^^^^
  File "<frozen importlib._bootstrap>", line 1204, in _gcd_import
  File "<frozen importlib._bootstrap>", line 1176, in _find_and_load
  File "<frozen importlib._bootstrap>", line 1147, in _find_and_load_unlocked
  File "<frozen importlib._bootstrap>", line 690, in _load_unlocked
  File "<frozen importlib._bootstrap_external>", line 940, in exec_module
  File "<frozen importlib._bootstrap>", line 241, in _call_with_frames_removed
  File "/app/driver.py", line 5, in <module>
    from api import create_app
  File "/app/api/__init__.py", line 7, in <module>
    from api.routes.verify_proxy import verify_bp
ModuleNotFoundError: No module named 'api.routes.verify_proxy'; 'api.routes' is not a package
[2025-05-16 17:45:08 +0000] [30] [ERROR] Exception in worker process
Traceback (most recent call last):
  File "/venv/lib/python3.11/site-packages/gunicorn/arbiter.py", line 608, in spawn_worker
    worker.init_process()
  File "/venv/lib/python3.11/site-packages/gunicorn/workers/ggevent.py", line 146, in init_process
    super().init_process()
  File "/venv/lib/python3.11/site-packages/gunicorn/workers/base.py", line 135, in init_process
    self.load_wsgi()
  File "/venv/lib/python3.11/site-packages/gunicorn/workers/base.py", line 147, in load_wsgi
    self.wsgi = self.app.wsgi()
                ^^^^^^^^^^^^^^^
  File "/venv/lib/python3.11/site-packages/gunicorn/app/base.py", line 66, in wsgi
    self.callable = self.load()
                    ^^^^^^^^^^^
  File "/venv/lib/python3.11/site-packages/gunicorn/app/wsgiapp.py", line 57, in load
    return self.load_wsgiapp()
           ^^^^^^^^^^^^^^^^^^^
  File "/venv/lib/python3.11/site-packages/gunicorn/app/wsgiapp.py", line 47, in load_wsgiapp
    return util.import_app(self.app_uri)
           ^^^^^^^^^^^^^^^^^^^^^^^^^^^^^
  File "/venv/lib/python3.11/site-packages/gunicorn/util.py", line 370, in import_app
    mod = importlib.import_module(module)
          ^^^^^^^^^^^^^^^^^^^^^^^^^^^^^^^
  File "/usr/lib/python3.11/importlib/__init__.py", line 126, in import_module
    return _bootstrap._gcd_import(name[level:], package, level)
           ^^^^^^^^^^^^^^^^^^^^^^^^^^^^^^^^^^^^^^^^^^^^^^^^^^^^
  File "<frozen importlib._bootstrap>", line 1204, in _gcd_import
  File "<frozen importlib._bootstrap>", line 1176, in _find_and_load
  File "<frozen importlib._bootstrap>", line 1147, in _find_and_load_unlocked
  File "<frozen importlib._bootstrap>", line 690, in _load_unlocked
  File "<frozen importlib._bootstrap_external>", line 940, in exec_module
  File "<frozen importlib._bootstrap>", line 241, in _call_with_frames_removed
  File "/app/driver.py", line 5, in <module>
    from api import create_app
  File "/app/api/__init__.py", line 7, in <module>
    from api.routes.verify_proxy import verify_bp
ModuleNotFoundError: No module named 'api.routes.verify_proxy'; 'api.routes' is not a package
[2025-05-16 17:45:08 +0000] [26] [ERROR] Exception in worker process
Traceback (most recent call last):
  File "/venv/lib/python3.11/site-packages/gunicorn/arbiter.py", line 608, in spawn_worker
    worker.init_process()
  File "/venv/lib/python3.11/site-packages/gunicorn/workers/ggevent.py", line 146, in init_process
    super().init_process()
  File "/venv/lib/python3.11/site-packages/gunicorn/workers/base.py", line 135, in init_process
    self.load_wsgi()
  File "/venv/lib/python3.11/site-packages/gunicorn/workers/base.py", line 147, in load_wsgi
    self.wsgi = self.app.wsgi()
                ^^^^^^^^^^^^^^^
  File "/venv/lib/python3.11/site-packages/gunicorn/app/base.py", line 66, in wsgi
    self.callable = self.load()
                    ^^^^^^^^^^^
  File "/venv/lib/python3.11/site-packages/gunicorn/app/wsgiapp.py", line 57, in load
    return self.load_wsgiapp()
           ^^^^^^^^^^^^^^^^^^^
  File "/venv/lib/python3.11/site-packages/gunicorn/app/wsgiapp.py", line 47, in load_wsgiapp
    return util.import_app(self.app_uri)
           ^^^^^^^^^^^^^^^^^^^^^^^^^^^^^
  File "/venv/lib/python3.11/site-packages/gunicorn/util.py", line 370, in import_app
    mod = importlib.import_module(module)
          ^^^^^^^^^^^^^^^^^^^^^^^^^^^^^^^
  File "/usr/lib/python3.11/importlib/__init__.py", line 126, in import_module
    return _bootstrap._gcd_import(name[level:], package, level)
           ^^^^^^^^^^^^^^^^^^^^^^^^^^^^^^^^^^^^^^^^^^^^^^^^^^^^
  File "<frozen importlib._bootstrap>", line 1204, in _gcd_import
  File "<frozen importlib._bootstrap>", line 1176, in _find_and_load
  File "<frozen importlib._bootstrap>", line 1147, in _find_and_load_unlocked
  File "<frozen importlib._bootstrap>", line 690, in _load_unlocked
  File "<frozen importlib._bootstrap_external>", line 940, in exec_module
  File "<frozen importlib._bootstrap>", line 241, in _call_with_frames_removed
  File "/app/driver.py", line 5, in <module>
    from api import create_app
  File "/app/api/__init__.py", line 7, in <module>
    from api.routes.verify_proxy import verify_bp
ModuleNotFoundError: No module named 'api.routes.verify_proxy'; 'api.routes' is not a package
[2025-05-16 17:45:08 +0000] [27] [INFO] Worker exiting (pid: 27)
[2025-05-16 17:45:08 +0000] [30] [INFO] Worker exiting (pid: 30)
[2025-05-16 17:45:08 +0000] [26] [INFO] Worker exiting (pid: 26)
[2025-05-16 17:45:08 +0000] [29] [ERROR] Exception in worker process
Traceback (most recent call last):
  File "/venv/lib/python3.11/site-packages/gunicorn/arbiter.py", line 608, in spawn_worker
    worker.init_process()
  File "/venv/lib/python3.11/site-packages/gunicorn/workers/ggevent.py", line 146, in init_process
    super().init_process()
  File "/venv/lib/python3.11/site-packages/gunicorn/workers/base.py", line 135, in init_process
    self.load_wsgi()
  File "/venv/lib/python3.11/site-packages/gunicorn/workers/base.py", line 147, in load_wsgi
    self.wsgi = self.app.wsgi()
                ^^^^^^^^^^^^^^^
  File "/venv/lib/python3.11/site-packages/gunicorn/app/base.py", line 66, in wsgi
    self.callable = self.load()
                    ^^^^^^^^^^^
  File "/venv/lib/python3.11/site-packages/gunicorn/app/wsgiapp.py", line 57, in load
    return self.load_wsgiapp()
           ^^^^^^^^^^^^^^^^^^^
  File "/venv/lib/python3.11/site-packages/gunicorn/app/wsgiapp.py", line 47, in load_wsgiapp
    return util.import_app(self.app_uri)
           ^^^^^^^^^^^^^^^^^^^^^^^^^^^^^
  File "/venv/lib/python3.11/site-packages/gunicorn/util.py", line 370, in import_app
    mod = importlib.import_module(module)
          ^^^^^^^^^^^^^^^^^^^^^^^^^^^^^^^
  File "/usr/lib/python3.11/importlib/__init__.py", line 126, in import_module
    return _bootstrap._gcd_import(name[level:], package, level)
           ^^^^^^^^^^^^^^^^^^^^^^^^^^^^^^^^^^^^^^^^^^^^^^^^^^^^
  File "<frozen importlib._bootstrap>", line 1204, in _gcd_import
  File "<frozen importlib._bootstrap>", line 1176, in _find_and_load
  File "<frozen importlib._bootstrap>", line 1147, in _find_and_load_unlocked
  File "<frozen importlib._bootstrap>", line 690, in _load_unlocked
  File "<frozen importlib._bootstrap_external>", line 940, in exec_module
  File "<frozen importlib._bootstrap>", line 241, in _call_with_frames_removed
  File "/app/driver.py", line 5, in <module>
    from api import create_app
  File "/app/api/__init__.py", line 7, in <module>
    from api.routes.verify_proxy import verify_bp
ModuleNotFoundError: No module named 'api.routes.verify_proxy'; 'api.routes' is not a package
[2025-05-16 17:45:08 +0000] [29] [INFO] Worker exiting (pid: 29)
[2025-05-16 17:45:08 +0000] [34] [ERROR] Exception in worker process
Traceback (most recent call last):
  File "/venv/lib/python3.11/site-packages/gunicorn/arbiter.py", line 608, in spawn_worker
    worker.init_process()
  File "/venv/lib/python3.11/site-packages/gunicorn/workers/ggevent.py", line 146, in init_process
    super().init_process()
  File "/venv/lib/python3.11/site-packages/gunicorn/workers/base.py", line 135, in init_process
    self.load_wsgi()
  File "/venv/lib/python3.11/site-packages/gunicorn/workers/base.py", line 147, in load_wsgi
    self.wsgi = self.app.wsgi()
                ^^^^^^^^^^^^^^^
  File "/venv/lib/python3.11/site-packages/gunicorn/app/base.py", line 66, in wsgi
    self.callable = self.load()
                    ^^^^^^^^^^^
  File "/venv/lib/python3.11/site-packages/gunicorn/app/wsgiapp.py", line 57, in load
    return self.load_wsgiapp()
           ^^^^^^^^^^^^^^^^^^^
  File "/venv/lib/python3.11/site-packages/gunicorn/app/wsgiapp.py", line 47, in load_wsgiapp
    return util.import_app(self.app_uri)
           ^^^^^^^^^^^^^^^^^^^^^^^^^^^^^
  File "/venv/lib/python3.11/site-packages/gunicorn/util.py", line 370, in import_app
    mod = importlib.import_module(module)
          ^^^^^^^^^^^^^^^^^^^^^^^^^^^^^^^
  File "/usr/lib/python3.11/importlib/__init__.py", line 126, in import_module
    return _bootstrap._gcd_import(name[level:], package, level)
           ^^^^^^^^^^^^^^^^^^^^^^^^^^^^^^^^^^^^^^^^^^^^^^^^^^^^
  File "<frozen importlib._bootstrap>", line 1204, in _gcd_import
  File "<frozen importlib._bootstrap>", line 1176, in _find_and_load
  File "<frozen importlib._bootstrap>", line 1147, in _find_and_load_unlocked
  File "<frozen importlib._bootstrap>", line 690, in _load_unlocked
  File "<frozen importlib._bootstrap_external>", line 940, in exec_module
  File "<frozen importlib._bootstrap>", line 241, in _call_with_frames_removed
  File "/app/driver.py", line 5, in <module>
    from api import create_app
  File "/app/api/__init__.py", line 7, in <module>
    from api.routes.verify_proxy import verify_bp
ModuleNotFoundError: No module named 'api.routes.verify_proxy'; 'api.routes' is not a package
[2025-05-16 17:45:08 +0000] [34] [INFO] Worker exiting (pid: 34)
[2025-05-16 17:45:08 +0000] [33] [ERROR] Exception in worker process
Traceback (most recent call last):
  File "/venv/lib/python3.11/site-packages/gunicorn/arbiter.py", line 608, in spawn_worker
    worker.init_process()
  File "/venv/lib/python3.11/site-packages/gunicorn/workers/ggevent.py", line 146, in init_process
    super().init_process()
  File "/venv/lib/python3.11/site-packages/gunicorn/workers/base.py", line 135, in init_process
    self.load_wsgi()
  File "/venv/lib/python3.11/site-packages/gunicorn/workers/base.py", line 147, in load_wsgi
    self.wsgi = self.app.wsgi()
                ^^^^^^^^^^^^^^^
  File "/venv/lib/python3.11/site-packages/gunicorn/app/base.py", line 66, in wsgi
    self.callable = self.load()
                    ^^^^^^^^^^^
  File "/venv/lib/python3.11/site-packages/gunicorn/app/wsgiapp.py", line 57, in load
    return self.load_wsgiapp()
           ^^^^^^^^^^^^^^^^^^^
  File "/venv/lib/python3.11/site-packages/gunicorn/app/wsgiapp.py", line 47, in load_wsgiapp
    return util.import_app(self.app_uri)
           ^^^^^^^^^^^^^^^^^^^^^^^^^^^^^
  File "/venv/lib/python3.11/site-packages/gunicorn/util.py", line 370, in import_app
    mod = importlib.import_module(module)
          ^^^^^^^^^^^^^^^^^^^^^^^^^^^^^^^
  File "/usr/lib/python3.11/importlib/__init__.py", line 126, in import_module
    return _bootstrap._gcd_import(name[level:], package, level)
           ^^^^^^^^^^^^^^^^^^^^^^^^^^^^^^^^^^^^^^^^^^^^^^^^^^^^
  File "<frozen importlib._bootstrap>", line 1204, in _gcd_import
  File "<frozen importlib._bootstrap>", line 1176, in _find_and_load
  File "<frozen importlib._bootstrap>", line 1147, in _find_and_load_unlocked
  File "<frozen importlib._bootstrap>", line 690, in _load_unlocked
  File "<frozen importlib._bootstrap_external>", line 940, in exec_module
  File "<frozen importlib._bootstrap>", line 241, in _call_with_frames_removed
  File "/app/driver.py", line 5, in <module>
    from api import create_app
  File "/app/api/__init__.py", line 7, in <module>
    from api.routes.verify_proxy import verify_bp
ModuleNotFoundError: No module named 'api.routes.verify_proxy'; 'api.routes' is not a package
[2025-05-16 17:45:08 +0000] [33] [INFO] Worker exiting (pid: 33)
[2025-05-16 17:45:08 +0000] [31] [ERROR] Exception in worker process
Traceback (most recent call last):
  File "/venv/lib/python3.11/site-packages/gunicorn/arbiter.py", line 608, in spawn_worker
    worker.init_process()
  File "/venv/lib/python3.11/site-packages/gunicorn/workers/ggevent.py", line 146, in init_process
    super().init_process()
  File "/venv/lib/python3.11/site-packages/gunicorn/workers/base.py", line 135, in init_process
    self.load_wsgi()
  File "/venv/lib/python3.11/site-packages/gunicorn/workers/base.py", line 147, in load_wsgi
    self.wsgi = self.app.wsgi()
                ^^^^^^^^^^^^^^^
  File "/venv/lib/python3.11/site-packages/gunicorn/app/base.py", line 66, in wsgi
    self.callable = self.load()
                    ^^^^^^^^^^^
  File "/venv/lib/python3.11/site-packages/gunicorn/app/wsgiapp.py", line 57, in load
    return self.load_wsgiapp()
           ^^^^^^^^^^^^^^^^^^^
  File "/venv/lib/python3.11/site-packages/gunicorn/app/wsgiapp.py", line 47, in load_wsgiapp
    return util.import_app(self.app_uri)
           ^^^^^^^^^^^^^^^^^^^^^^^^^^^^^
  File "/venv/lib/python3.11/site-packages/gunicorn/util.py", line 370, in import_app
    mod = importlib.import_module(module)
          ^^^^^^^^^^^^^^^^^^^^^^^^^^^^^^^
  File "/usr/lib/python3.11/importlib/__init__.py", line 126, in import_module
    return _bootstrap._gcd_import(name[level:], package, level)
           ^^^^^^^^^^^^^^^^^^^^^^^^^^^^^^^^^^^^^^^^^^^^^^^^^^^^
  File "<frozen importlib._bootstrap>", line 1204, in _gcd_import
  File "<frozen importlib._bootstrap>", line 1176, in _find_and_load
  File "<frozen importlib._bootstrap>", line 1147, in _find_and_load_unlocked
  File "<frozen importlib._bootstrap>", line 690, in _load_unlocked
  File "<frozen importlib._bootstrap_external>", line 940, in exec_module
  File "<frozen importlib._bootstrap>", line 241, in _call_with_frames_removed
  File "/app/driver.py", line 5, in <module>
    from api import create_app
  File "/app/api/__init__.py", line 7, in <module>
    from api.routes.verify_proxy import verify_bp
ModuleNotFoundError: No module named 'api.routes.verify_proxy'; 'api.routes' is not a package
[2025-05-16 17:45:08 +0000] [31] [INFO] Worker exiting (pid: 31)
[2025-05-16 17:45:08 +0000] [35] [ERROR] Exception in worker process
Traceback (most recent call last):
  File "/venv/lib/python3.11/site-packages/gunicorn/arbiter.py", line 608, in spawn_worker
    worker.init_process()
  File "/venv/lib/python3.11/site-packages/gunicorn/workers/ggevent.py", line 146, in init_process
    super().init_process()
  File "/venv/lib/python3.11/site-packages/gunicorn/workers/base.py", line 135, in init_process
    self.load_wsgi()
  File "/venv/lib/python3.11/site-packages/gunicorn/workers/base.py", line 147, in load_wsgi
    self.wsgi = self.app.wsgi()
                ^^^^^^^^^^^^^^^
  File "/venv/lib/python3.11/site-packages/gunicorn/app/base.py", line 66, in wsgi
    self.callable = self.load()
                    ^^^^^^^^^^^
  File "/venv/lib/python3.11/site-packages/gunicorn/app/wsgiapp.py", line 57, in load
    return self.load_wsgiapp()
           ^^^^^^^^^^^^^^^^^^^
  File "/venv/lib/python3.11/site-packages/gunicorn/app/wsgiapp.py", line 47, in load_wsgiapp
    return util.import_app(self.app_uri)
           ^^^^^^^^^^^^^^^^^^^^^^^^^^^^^
  File "/venv/lib/python3.11/site-packages/gunicorn/util.py", line 370, in import_app
    mod = importlib.import_module(module)
          ^^^^^^^^^^^^^^^^^^^^^^^^^^^^^^^
  File "/usr/lib/python3.11/importlib/__init__.py", line 126, in import_module
    return _bootstrap._gcd_import(name[level:], package, level)
           ^^^^^^^^^^^^^^^^^^^^^^^^^^^^^^^^^^^^^^^^^^^^^^^^^^^^
  File "<frozen importlib._bootstrap>", line 1204, in _gcd_import
  File "<frozen importlib._bootstrap>", line 1176, in _find_and_load
  File "<frozen importlib._bootstrap>", line 1147, in _find_and_load_unlocked
  File "<frozen importlib._bootstrap>", line 690, in _load_unlocked
  File "<frozen importlib._bootstrap_external>", line 940, in exec_module
  File "<frozen importlib._bootstrap>", line 241, in _call_with_frames_removed
  File "/app/driver.py", line 5, in <module>
    from api import create_app
  File "/app/api/__init__.py", line 7, in <module>
    from api.routes.verify_proxy import verify_bp
ModuleNotFoundError: No module named 'api.routes.verify_proxy'; 'api.routes' is not a package
[2025-05-16 17:45:08 +0000] [35] [INFO] Worker exiting (pid: 35)
[2025-05-16 17:45:09 +0000] [17] [ERROR] Worker (pid:28) exited with code 3
[2025-05-16 17:45:09 +0000] [17] [ERROR] Worker (pid:29) exited with code 3
Traceback (most recent call last):
  File "/venv/lib/python3.11/site-packages/gunicorn/arbiter.py", line 208, in run
    self.sleep()
  File "/venv/lib/python3.11/site-packages/gunicorn/arbiter.py", line 359, in sleep
    ready = select.select([self.PIPE[0]], [], [], 1.0)
            ^^^^^^^^^^^^^^^^^^^^^^^^^^^^^^^^^^^^^^^^^^
  File "/venv/lib/python3.11/site-packages/gunicorn/arbiter.py", line 241, in handle_chld
    self.reap_workers()
  File "/venv/lib/python3.11/site-packages/gunicorn/arbiter.py", line 529, in reap_workers
    raise HaltServer(reason, self.WORKER_BOOT_ERROR)
gunicorn.errors.HaltServer: <HaltServer 'Worker failed to boot.' 3>

During handling of the above exception, another exception occurred:

Traceback (most recent call last):
  File "/venv/bin/gunicorn", line 8, in <module>
    sys.exit(run())
             ^^^^^
  File "/venv/lib/python3.11/site-packages/gunicorn/app/wsgiapp.py", line 66, in run
    WSGIApplication("%(prog)s [OPTIONS] [APP_MODULE]", prog=prog).run()
  File "/venv/lib/python3.11/site-packages/gunicorn/app/base.py", line 235, in run
    super().run()
  File "/venv/lib/python3.11/site-packages/gunicorn/app/base.py", line 71, in run
    Arbiter(self).run()
  File "/venv/lib/python3.11/site-packages/gunicorn/arbiter.py", line 228, in run
    self.halt(reason=inst.reason, exit_status=inst.exit_status)
  File "/venv/lib/python3.11/site-packages/gunicorn/arbiter.py", line 341, in halt
    self.stop()
  File "/venv/lib/python3.11/site-packages/gunicorn/arbiter.py", line 395, in stop
    time.sleep(0.1)
  File "/venv/lib/python3.11/site-packages/gunicorn/arbiter.py", line 241, in handle_chld
    self.reap_workers()
  File "/venv/lib/python3.11/site-packages/gunicorn/arbiter.py", line 529, in reap_workers
    raise HaltServer(reason, self.WORKER_BOOT_ERROR)
gunicorn.errors.HaltServer: <HaltServer 'Worker failed to boot.' 3>
[2025-05-16 17:45:09 +0000] [44] [INFO] Starting gunicorn 23.0.0
[2025-05-16 17:45:09 +0000] [44] [INFO] Listening at: https://0.0.0.0:5000 (44)
[2025-05-16 17:45:09 +0000] [44] [INFO] Using worker: gevent
[2025-05-16 17:45:09 +0000] [46] [INFO] Booting worker with pid: 46
[2025-05-16 17:45:09 +0000] [53] [INFO] Booting worker with pid: 53
[2025-05-16 17:45:09 +0000] [54] [INFO] Booting worker with pid: 54
[2025-05-16 17:45:09 +0000] [55] [INFO] Booting worker with pid: 55
[2025-05-16 17:45:09 +0000] [56] [INFO] Booting worker with pid: 56
[2025-05-16 17:45:09 +0000] [57] [INFO] Booting worker with pid: 57
[2025-05-16 17:45:10 +0000] [58] [INFO] Booting worker with pid: 58
[2025-05-16 17:45:10 +0000] [59] [INFO] Booting worker with pid: 59
[2025-05-16 17:45:10 +0000] [60] [INFO] Booting worker with pid: 60
[2025-05-16 17:45:11 +0000] [46] [ERROR] Exception in worker process
Traceback (most recent call last):
  File "/venv/lib/python3.11/site-packages/gunicorn/arbiter.py", line 608, in spawn_worker
    worker.init_process()
  File "/venv/lib/python3.11/site-packages/gunicorn/workers/ggevent.py", line 146, in init_process
    super().init_process()
  File "/venv/lib/python3.11/site-packages/gunicorn/workers/base.py", line 135, in init_process
    self.load_wsgi()
  File "/venv/lib/python3.11/site-packages/gunicorn/workers/base.py", line 147, in load_wsgi
    self.wsgi = self.app.wsgi()
                ^^^^^^^^^^^^^^^
  File "/venv/lib/python3.11/site-packages/gunicorn/app/base.py", line 66, in wsgi
    self.callable = self.load()
                    ^^^^^^^^^^^
  File "/venv/lib/python3.11/site-packages/gunicorn/app/wsgiapp.py", line 57, in load
    return self.load_wsgiapp()
           ^^^^^^^^^^^^^^^^^^^
  File "/venv/lib/python3.11/site-packages/gunicorn/app/wsgiapp.py", line 47, in load_wsgiapp
    return util.import_app(self.app_uri)
           ^^^^^^^^^^^^^^^^^^^^^^^^^^^^^
  File "/venv/lib/python3.11/site-packages/gunicorn/util.py", line 370, in import_app
    mod = importlib.import_module(module)
          ^^^^^^^^^^^^^^^^^^^^^^^^^^^^^^^
  File "/usr/lib/python3.11/importlib/__init__.py", line 126, in import_module
    return _bootstrap._gcd_import(name[level:], package, level)
           ^^^^^^^^^^^^^^^^^^^^^^^^^^^^^^^^^^^^^^^^^^^^^^^^^^^^
  File "<frozen importlib._bootstrap>", line 1204, in _gcd_import
  File "<frozen importlib._bootstrap>", line 1176, in _find_and_load
  File "<frozen importlib._bootstrap>", line 1147, in _find_and_load_unlocked
  File "<frozen importlib._bootstrap>", line 690, in _load_unlocked
  File "<frozen importlib._bootstrap_external>", line 940, in exec_module
  File "<frozen importlib._bootstrap>", line 241, in _call_with_frames_removed
  File "/app/driver.py", line 5, in <module>
    from api import create_app
  File "/app/api/__init__.py", line 7, in <module>
    from api.routes.verify_proxy import verify_bp
ModuleNotFoundError: No module named 'api.routes.verify_proxy'; 'api.routes' is not a package
[2025-05-16 17:45:11 +0000] [46] [INFO] Worker exiting (pid: 46)
[2025-05-16 17:45:11 +0000] [55] [ERROR] Exception in worker process
Traceback (most recent call last):
  File "/venv/lib/python3.11/site-packages/gunicorn/arbiter.py", line 608, in spawn_worker
    worker.init_process()
  File "/venv/lib/python3.11/site-packages/gunicorn/workers/ggevent.py", line 146, in init_process
    super().init_process()
  File "/venv/lib/python3.11/site-packages/gunicorn/workers/base.py", line 135, in init_process
    self.load_wsgi()
  File "/venv/lib/python3.11/site-packages/gunicorn/workers/base.py", line 147, in load_wsgi
    self.wsgi = self.app.wsgi()
                ^^^^^^^^^^^^^^^
  File "/venv/lib/python3.11/site-packages/gunicorn/app/base.py", line 66, in wsgi
    self.callable = self.load()
                    ^^^^^^^^^^^
  File "/venv/lib/python3.11/site-packages/gunicorn/app/wsgiapp.py", line 57, in load
    return self.load_wsgiapp()
           ^^^^^^^^^^^^^^^^^^^
  File "/venv/lib/python3.11/site-packages/gunicorn/app/wsgiapp.py", line 47, in load_wsgiapp
    return util.import_app(self.app_uri)
           ^^^^^^^^^^^^^^^^^^^^^^^^^^^^^
  File "/venv/lib/python3.11/site-packages/gunicorn/util.py", line 370, in import_app
    mod = importlib.import_module(module)
          ^^^^^^^^^^^^^^^^^^^^^^^^^^^^^^^
  File "/usr/lib/python3.11/importlib/__init__.py", line 126, in import_module
    return _bootstrap._gcd_import(name[level:], package, level)
           ^^^^^^^^^^^^^^^^^^^^^^^^^^^^^^^^^^^^^^^^^^^^^^^^^^^^
  File "<frozen importlib._bootstrap>", line 1204, in _gcd_import
  File "<frozen importlib._bootstrap>", line 1176, in _find_and_load
  File "<frozen importlib._bootstrap>", line 1147, in _find_and_load_unlocked
  File "<frozen importlib._bootstrap>", line 690, in _load_unlocked
  File "<frozen importlib._bootstrap_external>", line 940, in exec_module
  File "<frozen importlib._bootstrap>", line 241, in _call_with_frames_removed
  File "/app/driver.py", line 5, in <module>
    from api import create_app
  File "/app/api/__init__.py", line 7, in <module>
    from api.routes.verify_proxy import verify_bp
ModuleNotFoundError: No module named 'api.routes.verify_proxy'; 'api.routes' is not a package
[2025-05-16 17:45:11 +0000] [55] [INFO] Worker exiting (pid: 55)
[2025-05-16 17:45:11 +0000] [53] [ERROR] Exception in worker process
Traceback (most recent call last):
  File "/venv/lib/python3.11/site-packages/gunicorn/arbiter.py", line 608, in spawn_worker
    worker.init_process()
  File "/venv/lib/python3.11/site-packages/gunicorn/workers/ggevent.py", line 146, in init_process
    super().init_process()
  File "/venv/lib/python3.11/site-packages/gunicorn/workers/base.py", line 135, in init_process
    self.load_wsgi()
  File "/venv/lib/python3.11/site-packages/gunicorn/workers/base.py", line 147, in load_wsgi
    self.wsgi = self.app.wsgi()
                ^^^^^^^^^^^^^^^
  File "/venv/lib/python3.11/site-packages/gunicorn/app/base.py", line 66, in wsgi
    self.callable = self.load()
                    ^^^^^^^^^^^
  File "/venv/lib/python3.11/site-packages/gunicorn/app/wsgiapp.py", line 57, in load
    return self.load_wsgiapp()
           ^^^^^^^^^^^^^^^^^^^
  File "/venv/lib/python3.11/site-packages/gunicorn/app/wsgiapp.py", line 47, in load_wsgiapp
    return util.import_app(self.app_uri)
           ^^^^^^^^^^^^^^^^^^^^^^^^^^^^^
  File "/venv/lib/python3.11/site-packages/gunicorn/util.py", line 370, in import_app
    mod = importlib.import_module(module)
          ^^^^^^^^^^^^^^^^^^^^^^^^^^^^^^^
  File "/usr/lib/python3.11/importlib/__init__.py", line 126, in import_module
    return _bootstrap._gcd_import(name[level:], package, level)
           ^^^^^^^^^^^^^^^^^^^^^^^^^^^^^^^^^^^^^^^^^^^^^^^^^^^^
  File "<frozen importlib._bootstrap>", line 1204, in _gcd_import
  File "<frozen importlib._bootstrap>", line 1176, in _find_and_load
  File "<frozen importlib._bootstrap>", line 1147, in _find_and_load_unlocked
  File "<frozen importlib._bootstrap>", line 690, in _load_unlocked
  File "<frozen importlib._bootstrap_external>", line 940, in exec_module
  File "<frozen importlib._bootstrap>", line 241, in _call_with_frames_removed
  File "/app/driver.py", line 5, in <module>
    from api import create_app
  File "/app/api/__init__.py", line 7, in <module>
    from api.routes.verify_proxy import verify_bp
ModuleNotFoundError: No module named 'api.routes.verify_proxy'; 'api.routes' is not a package
[2025-05-16 17:45:11 +0000] [53] [INFO] Worker exiting (pid: 53)
[2025-05-16 17:45:11 +0000] [57] [ERROR] Exception in worker process
Traceback (most recent call last):
  File "/venv/lib/python3.11/site-packages/gunicorn/arbiter.py", line 608, in spawn_worker
    worker.init_process()
  File "/venv/lib/python3.11/site-packages/gunicorn/workers/ggevent.py", line 146, in init_process
    super().init_process()
  File "/venv/lib/python3.11/site-packages/gunicorn/workers/base.py", line 135, in init_process
    self.load_wsgi()
  File "/venv/lib/python3.11/site-packages/gunicorn/workers/base.py", line 147, in load_wsgi
    self.wsgi = self.app.wsgi()
                ^^^^^^^^^^^^^^^
  File "/venv/lib/python3.11/site-packages/gunicorn/app/base.py", line 66, in wsgi
    self.callable = self.load()
                    ^^^^^^^^^^^
  File "/venv/lib/python3.11/site-packages/gunicorn/app/wsgiapp.py", line 57, in load
    return self.load_wsgiapp()
           ^^^^^^^^^^^^^^^^^^^
  File "/venv/lib/python3.11/site-packages/gunicorn/app/wsgiapp.py", line 47, in load_wsgiapp
    return util.import_app(self.app_uri)
           ^^^^^^^^^^^^^^^^^^^^^^^^^^^^^
  File "/venv/lib/python3.11/site-packages/gunicorn/util.py", line 370, in import_app
    mod = importlib.import_module(module)
          ^^^^^^^^^^^^^^^^^^^^^^^^^^^^^^^
  File "/usr/lib/python3.11/importlib/__init__.py", line 126, in import_module
    return _bootstrap._gcd_import(name[level:], package, level)
           ^^^^^^^^^^^^^^^^^^^^^^^^^^^^^^^^^^^^^^^^^^^^^^^^^^^^
  File "<frozen importlib._bootstrap>", line 1204, in _gcd_import
  File "<frozen importlib._bootstrap>", line 1176, in _find_and_load
  File "<frozen importlib._bootstrap>", line 1147, in _find_and_load_unlocked
  File "<frozen importlib._bootstrap>", line 690, in _load_unlocked
  File "<frozen importlib._bootstrap_external>", line 940, in exec_module
  File "<frozen importlib._bootstrap>", line 241, in _call_with_frames_removed
  File "/app/driver.py", line 5, in <module>
    from api import create_app
  File "/app/api/__init__.py", line 7, in <module>
    from api.routes.verify_proxy import verify_bp
ModuleNotFoundError: No module named 'api.routes.verify_proxy'; 'api.routes' is not a package
[2025-05-16 17:45:11 +0000] [57] [INFO] Worker exiting (pid: 57)
[2025-05-16 17:45:11 +0000] [54] [ERROR] Exception in worker process
Traceback (most recent call last):
  File "/venv/lib/python3.11/site-packages/gunicorn/arbiter.py", line 608, in spawn_worker
    worker.init_process()
  File "/venv/lib/python3.11/site-packages/gunicorn/workers/ggevent.py", line 146, in init_process
    super().init_process()
  File "/venv/lib/python3.11/site-packages/gunicorn/workers/base.py", line 135, in init_process
    self.load_wsgi()
  File "/venv/lib/python3.11/site-packages/gunicorn/workers/base.py", line 147, in load_wsgi
    self.wsgi = self.app.wsgi()
                ^^^^^^^^^^^^^^^
  File "/venv/lib/python3.11/site-packages/gunicorn/app/base.py", line 66, in wsgi
    self.callable = self.load()
                    ^^^^^^^^^^^
  File "/venv/lib/python3.11/site-packages/gunicorn/app/wsgiapp.py", line 57, in load
    return self.load_wsgiapp()
           ^^^^^^^^^^^^^^^^^^^
  File "/venv/lib/python3.11/site-packages/gunicorn/app/wsgiapp.py", line 47, in load_wsgiapp
    return util.import_app(self.app_uri)
           ^^^^^^^^^^^^^^^^^^^^^^^^^^^^^
  File "/venv/lib/python3.11/site-packages/gunicorn/util.py", line 370, in import_app
    mod = importlib.import_module(module)
          ^^^^^^^^^^^^^^^^^^^^^^^^^^^^^^^
  File "/usr/lib/python3.11/importlib/__init__.py", line 126, in import_module
    return _bootstrap._gcd_import(name[level:], package, level)
           ^^^^^^^^^^^^^^^^^^^^^^^^^^^^^^^^^^^^^^^^^^^^^^^^^^^^
  File "<frozen importlib._bootstrap>", line 1204, in _gcd_import
  File "<frozen importlib._bootstrap>", line 1176, in _find_and_load
  File "<frozen importlib._bootstrap>", line 1147, in _find_and_load_unlocked
  File "<frozen importlib._bootstrap>", line 690, in _load_unlocked
  File "<frozen importlib._bootstrap_external>", line 940, in exec_module
  File "<frozen importlib._bootstrap>", line 241, in _call_with_frames_removed
  File "/app/driver.py", line 5, in <module>
    from api import create_app
  File "/app/api/__init__.py", line 7, in <module>
    from api.routes.verify_proxy import verify_bp
ModuleNotFoundError: No module named 'api.routes.verify_proxy'; 'api.routes' is not a package
[2025-05-16 17:45:11 +0000] [54] [INFO] Worker exiting (pid: 54)
[2025-05-16 17:45:11 +0000] [44] [ERROR] Worker (pid:46) exited with code 3
[2025-05-16 17:45:11 +0000] [44] [ERROR] Worker (pid:53) was sent SIGTERM!
[2025-05-16 17:45:11 +0000] [44] [ERROR] Worker (pid:54) was sent SIGTERM!
[2025-05-16 17:45:11 +0000] [44] [ERROR] Worker (pid:55) was sent SIGTERM!
[2025-05-16 17:45:11 +0000] [44] [ERROR] Worker (pid:57) was sent SIGTERM!
[2025-05-16 17:45:11 +0000] [56] [ERROR] Exception in worker process
Traceback (most recent call last):
  File "/venv/lib/python3.11/site-packages/gunicorn/arbiter.py", line 608, in spawn_worker
    worker.init_process()
  File "/venv/lib/python3.11/site-packages/gunicorn/workers/ggevent.py", line 146, in init_process
    super().init_process()
  File "/venv/lib/python3.11/site-packages/gunicorn/workers/base.py", line 135, in init_process
    self.load_wsgi()
  File "/venv/lib/python3.11/site-packages/gunicorn/workers/base.py", line 147, in load_wsgi
    self.wsgi = self.app.wsgi()
                ^^^^^^^^^^^^^^^
  File "/venv/lib/python3.11/site-packages/gunicorn/app/base.py", line 66, in wsgi
    self.callable = self.load()
                    ^^^^^^^^^^^
  File "/venv/lib/python3.11/site-packages/gunicorn/app/wsgiapp.py", line 57, in load
    return self.load_wsgiapp()
           ^^^^^^^^^^^^^^^^^^^
  File "/venv/lib/python3.11/site-packages/gunicorn/app/wsgiapp.py", line 47, in load_wsgiapp
    return util.import_app(self.app_uri)
           ^^^^^^^^^^^^^^^^^^^^^^^^^^^^^
  File "/venv/lib/python3.11/site-packages/gunicorn/util.py", line 370, in import_app
    mod = importlib.import_module(module)
          ^^^^^^^^^^^^^^^^^^^^^^^^^^^^^^^
  File "/usr/lib/python3.11/importlib/__init__.py", line 126, in import_module
    return _bootstrap._gcd_import(name[level:], package, level)
           ^^^^^^^^^^^^^^^^^^^^^^^^^^^^^^^^^^^^^^^^^^^^^^^^^^^^
  File "<frozen importlib._bootstrap>", line 1204, in _gcd_import
  File "<frozen importlib._bootstrap>", line 1176, in _find_and_load
  File "<frozen importlib._bootstrap>", line 1147, in _find_and_load_unlocked
  File "<frozen importlib._bootstrap>", line 690, in _load_unlocked
  File "<frozen importlib._bootstrap_external>", line 940, in exec_module
  File "<frozen importlib._bootstrap>", line 241, in _call_with_frames_removed
  File "/app/driver.py", line 5, in <module>
    from api import create_app
  File "/app/api/__init__.py", line 7, in <module>
    from api.routes.verify_proxy import verify_bp
ModuleNotFoundError: No module named 'api.routes.verify_proxy'; 'api.routes' is not a package
[2025-05-16 17:45:11 +0000] [56] [INFO] Worker exiting (pid: 56)
[2025-05-16 17:45:11 +0000] [58] [ERROR] Exception in worker process
Traceback (most recent call last):
  File "/venv/lib/python3.11/site-packages/gunicorn/arbiter.py", line 608, in spawn_worker
    worker.init_process()
  File "/venv/lib/python3.11/site-packages/gunicorn/workers/ggevent.py", line 146, in init_process
    super().init_process()
  File "/venv/lib/python3.11/site-packages/gunicorn/workers/base.py", line 135, in init_process
    self.load_wsgi()
  File "/venv/lib/python3.11/site-packages/gunicorn/workers/base.py", line 147, in load_wsgi
    self.wsgi = self.app.wsgi()
                ^^^^^^^^^^^^^^^
  File "/venv/lib/python3.11/site-packages/gunicorn/app/base.py", line 66, in wsgi
    self.callable = self.load()
                    ^^^^^^^^^^^
  File "/venv/lib/python3.11/site-packages/gunicorn/app/wsgiapp.py", line 57, in load
    return self.load_wsgiapp()
           ^^^^^^^^^^^^^^^^^^^
  File "/venv/lib/python3.11/site-packages/gunicorn/app/wsgiapp.py", line 47, in load_wsgiapp
    return util.import_app(self.app_uri)
           ^^^^^^^^^^^^^^^^^^^^^^^^^^^^^
  File "/venv/lib/python3.11/site-packages/gunicorn/util.py", line 370, in import_app
    mod = importlib.import_module(module)
          ^^^^^^^^^^^^^^^^^^^^^^^^^^^^^^^
  File "/usr/lib/python3.11/importlib/__init__.py", line 126, in import_module
    return _bootstrap._gcd_import(name[level:], package, level)
           ^^^^^^^^^^^^^^^^^^^^^^^^^^^^^^^^^^^^^^^^^^^^^^^^^^^^
  File "<frozen importlib._bootstrap>", line 1204, in _gcd_import
  File "<frozen importlib._bootstrap>", line 1176, in _find_and_load
  File "<frozen importlib._bootstrap>", line 1147, in _find_and_load_unlocked
  File "<frozen importlib._bootstrap>", line 690, in _load_unlocked
  File "<frozen importlib._bootstrap_external>", line 940, in exec_module
  File "<frozen importlib._bootstrap>", line 241, in _call_with_frames_removed
  File "/app/driver.py", line 5, in <module>
    from api import create_app
  File "/app/api/__init__.py", line 7, in <module>
    from api.routes.verify_proxy import verify_bp
ModuleNotFoundError: No module named 'api.routes.verify_proxy'; 'api.routes' is not a package
[2025-05-16 17:45:11 +0000] [58] [INFO] Worker exiting (pid: 58)
[2025-05-16 17:45:11 +0000] [59] [ERROR] Exception in worker process
Traceback (most recent call last):
  File "/venv/lib/python3.11/site-packages/gunicorn/arbiter.py", line 608, in spawn_worker
    worker.init_process()
  File "/venv/lib/python3.11/site-packages/gunicorn/workers/ggevent.py", line 146, in init_process
    super().init_process()
  File "/venv/lib/python3.11/site-packages/gunicorn/workers/base.py", line 135, in init_process
    self.load_wsgi()
  File "/venv/lib/python3.11/site-packages/gunicorn/workers/base.py", line 147, in load_wsgi
    self.wsgi = self.app.wsgi()
                ^^^^^^^^^^^^^^^
  File "/venv/lib/python3.11/site-packages/gunicorn/app/base.py", line 66, in wsgi
    self.callable = self.load()
                    ^^^^^^^^^^^
  File "/venv/lib/python3.11/site-packages/gunicorn/app/wsgiapp.py", line 57, in load
    return self.load_wsgiapp()
           ^^^^^^^^^^^^^^^^^^^
  File "/venv/lib/python3.11/site-packages/gunicorn/app/wsgiapp.py", line 47, in load_wsgiapp
    return util.import_app(self.app_uri)
           ^^^^^^^^^^^^^^^^^^^^^^^^^^^^^
  File "/venv/lib/python3.11/site-packages/gunicorn/util.py", line 370, in import_app
    mod = importlib.import_module(module)
          ^^^^^^^^^^^^^^^^^^^^^^^^^^^^^^^
  File "/usr/lib/python3.11/importlib/__init__.py", line 126, in import_module
    return _bootstrap._gcd_import(name[level:], package, level)
           ^^^^^^^^^^^^^^^^^^^^^^^^^^^^^^^^^^^^^^^^^^^^^^^^^^^^
  File "<frozen importlib._bootstrap>", line 1204, in _gcd_import
  File "<frozen importlib._bootstrap>", line 1176, in _find_and_load
  File "<frozen importlib._bootstrap>", line 1147, in _find_and_load_unlocked
  File "<frozen importlib._bootstrap>", line 690, in _load_unlocked
  File "<frozen importlib._bootstrap_external>", line 940, in exec_module
  File "<frozen importlib._bootstrap>", line 241, in _call_with_frames_removed
  File "/app/driver.py", line 5, in <module>
    from api import create_app
  File "/app/api/__init__.py", line 7, in <module>
    from api.routes.verify_proxy import verify_bp
ModuleNotFoundError: No module named 'api.routes.verify_proxy'; 'api.routes' is not a package
[2025-05-16 17:45:11 +0000] [59] [INFO] Worker exiting (pid: 59)
[2025-05-16 17:45:11 +0000] [60] [ERROR] Exception in worker process
Traceback (most recent call last):
  File "/venv/lib/python3.11/site-packages/gunicorn/arbiter.py", line 608, in spawn_worker
    worker.init_process()
  File "/venv/lib/python3.11/site-packages/gunicorn/workers/ggevent.py", line 146, in init_process
    super().init_process()
  File "/venv/lib/python3.11/site-packages/gunicorn/workers/base.py", line 135, in init_process
    self.load_wsgi()
  File "/venv/lib/python3.11/site-packages/gunicorn/workers/base.py", line 147, in load_wsgi
    self.wsgi = self.app.wsgi()
                ^^^^^^^^^^^^^^^
  File "/venv/lib/python3.11/site-packages/gunicorn/app/base.py", line 66, in wsgi
    self.callable = self.load()
                    ^^^^^^^^^^^
  File "/venv/lib/python3.11/site-packages/gunicorn/app/wsgiapp.py", line 57, in load
    return self.load_wsgiapp()
           ^^^^^^^^^^^^^^^^^^^
  File "/venv/lib/python3.11/site-packages/gunicorn/app/wsgiapp.py", line 47, in load_wsgiapp
    return util.import_app(self.app_uri)
           ^^^^^^^^^^^^^^^^^^^^^^^^^^^^^
  File "/venv/lib/python3.11/site-packages/gunicorn/util.py", line 370, in import_app
    mod = importlib.import_module(module)
          ^^^^^^^^^^^^^^^^^^^^^^^^^^^^^^^
  File "/usr/lib/python3.11/importlib/__init__.py", line 126, in import_module
    return _bootstrap._gcd_import(name[level:], package, level)
           ^^^^^^^^^^^^^^^^^^^^^^^^^^^^^^^^^^^^^^^^^^^^^^^^^^^^
  File "<frozen importlib._bootstrap>", line 1204, in _gcd_import
  File "<frozen importlib._bootstrap>", line 1176, in _find_and_load
  File "<frozen importlib._bootstrap>", line 1147, in _find_and_load_unlocked
  File "<frozen importlib._bootstrap>", line 690, in _load_unlocked
  File "<frozen importlib._bootstrap_external>", line 940, in exec_module
  File "<frozen importlib._bootstrap>", line 241, in _call_with_frames_removed
  File "/app/driver.py", line 5, in <module>
    from api import create_app
  File "/app/api/__init__.py", line 7, in <module>
    from api.routes.verify_proxy import verify_bp
ModuleNotFoundError: No module named 'api.routes.verify_proxy'; 'api.routes' is not a package
[2025-05-16 17:45:11 +0000] [60] [INFO] Worker exiting (pid: 60)
[2025-05-16 17:45:11 +0000] [44] [ERROR] Worker (pid:56) exited with code 3
Traceback (most recent call last):
  File "/venv/lib/python3.11/site-packages/gunicorn/arbiter.py", line 208, in run
    self.sleep()
  File "/venv/lib/python3.11/site-packages/gunicorn/arbiter.py", line 359, in sleep
    ready = select.select([self.PIPE[0]], [], [], 1.0)
            ^^^^^^^^^^^^^^^^^^^^^^^^^^^^^^^^^^^^^^^^^^
  File "/venv/lib/python3.11/site-packages/gunicorn/arbiter.py", line 241, in handle_chld
    self.reap_workers()
  File "/venv/lib/python3.11/site-packages/gunicorn/arbiter.py", line 529, in reap_workers
    raise HaltServer(reason, self.WORKER_BOOT_ERROR)
gunicorn.errors.HaltServer: <HaltServer 'Worker failed to boot.' 3>

During handling of the above exception, another exception occurred:

Traceback (most recent call last):
  File "/venv/bin/gunicorn", line 8, in <module>
    sys.exit(run())
             ^^^^^
  File "/venv/lib/python3.11/site-packages/gunicorn/app/wsgiapp.py", line 66, in run
    WSGIApplication("%(prog)s [OPTIONS] [APP_MODULE]", prog=prog).run()
  File "/venv/lib/python3.11/site-packages/gunicorn/app/base.py", line 235, in run
    super().run()
  File "/venv/lib/python3.11/site-packages/gunicorn/app/base.py", line 71, in run
    Arbiter(self).run()
  File "/venv/lib/python3.11/site-packages/gunicorn/arbiter.py", line 228, in run
    self.halt(reason=inst.reason, exit_status=inst.exit_status)
  File "/venv/lib/python3.11/site-packages/gunicorn/arbiter.py", line 341, in halt
    self.stop()
  File "/venv/lib/python3.11/site-packages/gunicorn/arbiter.py", line 395, in stop
    time.sleep(0.1)
  File "/venv/lib/python3.11/site-packages/gunicorn/arbiter.py", line 241, in handle_chld
    self.reap_workers()
  File "/venv/lib/python3.11/site-packages/gunicorn/arbiter.py", line 529, in reap_workers
    raise HaltServer(reason, self.WORKER_BOOT_ERROR)
gunicorn.errors.HaltServer: <HaltServer 'Worker failed to boot.' 3>
[2025-05-16 17:45:12 +0000] [69] [INFO] Starting gunicorn 23.0.0
[2025-05-16 17:45:12 +0000] [69] [INFO] Listening at: https://0.0.0.0:5000 (69)
[2025-05-16 17:45:12 +0000] [69] [INFO] Using worker: gevent
[2025-05-16 17:45:12 +0000] [70] [INFO] Booting worker with pid: 70
[2025-05-16 17:45:12 +0000] [71] [INFO] Booting worker with pid: 71
[2025-05-16 17:45:12 +0000] [72] [INFO] Booting worker with pid: 72
[2025-05-16 17:45:12 +0000] [73] [INFO] Booting worker with pid: 73
[2025-05-16 17:45:12 +0000] [74] [INFO] Booting worker with pid: 74
[2025-05-16 17:45:12 +0000] [75] [INFO] Booting worker with pid: 75
[2025-05-16 17:45:12 +0000] [76] [INFO] Booting worker with pid: 76
[2025-05-16 17:45:12 +0000] [77] [INFO] Booting worker with pid: 77
[2025-05-16 17:45:12 +0000] [78] [INFO] Booting worker with pid: 78
[2025-05-16 17:45:13 +0000] [70] [ERROR] Exception in worker process
Traceback (most recent call last):
  File "/venv/lib/python3.11/site-packages/gunicorn/arbiter.py", line 608, in spawn_worker
    worker.init_process()
  File "/venv/lib/python3.11/site-packages/gunicorn/workers/ggevent.py", line 146, in init_process
    super().init_process()
  File "/venv/lib/python3.11/site-packages/gunicorn/workers/base.py", line 135, in init_process
    self.load_wsgi()
  File "/venv/lib/python3.11/site-packages/gunicorn/workers/base.py", line 147, in load_wsgi
    self.wsgi = self.app.wsgi()
                ^^^^^^^^^^^^^^^
  File "/venv/lib/python3.11/site-packages/gunicorn/app/base.py", line 66, in wsgi
    self.callable = self.load()
                    ^^^^^^^^^^^
  File "/venv/lib/python3.11/site-packages/gunicorn/app/wsgiapp.py", line 57, in load
    return self.load_wsgiapp()
           ^^^^^^^^^^^^^^^^^^^
  File "/venv/lib/python3.11/site-packages/gunicorn/app/wsgiapp.py", line 47, in load_wsgiapp
    return util.import_app(self.app_uri)
           ^^^^^^^^^^^^^^^^^^^^^^^^^^^^^
  File "/venv/lib/python3.11/site-packages/gunicorn/util.py", line 370, in import_app
    mod = importlib.import_module(module)
          ^^^^^^^^^^^^^^^^^^^^^^^^^^^^^^^
  File "/usr/lib/python3.11/importlib/__init__.py", line 126, in import_module
    return _bootstrap._gcd_import(name[level:], package, level)
           ^^^^^^^^^^^^^^^^^^^^^^^^^^^^^^^^^^^^^^^^^^^^^^^^^^^^
  File "<frozen importlib._bootstrap>", line 1204, in _gcd_import
  File "<frozen importlib._bootstrap>", line 1176, in _find_and_load
  File "<frozen importlib._bootstrap>", line 1147, in _find_and_load_unlocked
  File "<frozen importlib._bootstrap>", line 690, in _load_unlocked
  File "<frozen importlib._bootstrap_external>", line 940, in exec_module
  File "<frozen importlib._bootstrap>", line 241, in _call_with_frames_removed
  File "/app/driver.py", line 5, in <module>
    from api import create_app
  File "/app/api/__init__.py", line 7, in <module>
    from api.routes.verify_proxy import verify_bp
ModuleNotFoundError: No module named 'api.routes.verify_proxy'; 'api.routes' is not a package
[2025-05-16 17:45:13 +0000] [70] [INFO] Worker exiting (pid: 70)
[2025-05-16 17:45:13 +0000] [71] [ERROR] Exception in worker process
Traceback (most recent call last):
  File "/venv/lib/python3.11/site-packages/gunicorn/arbiter.py", line 608, in spawn_worker
    worker.init_process()
  File "/venv/lib/python3.11/site-packages/gunicorn/workers/ggevent.py", line 146, in init_process
    super().init_process()
  File "/venv/lib/python3.11/site-packages/gunicorn/workers/base.py", line 135, in init_process
    self.load_wsgi()
  File "/venv/lib/python3.11/site-packages/gunicorn/workers/base.py", line 147, in load_wsgi
    self.wsgi = self.app.wsgi()
                ^^^^^^^^^^^^^^^
  File "/venv/lib/python3.11/site-packages/gunicorn/app/base.py", line 66, in wsgi
    self.callable = self.load()
                    ^^^^^^^^^^^
  File "/venv/lib/python3.11/site-packages/gunicorn/app/wsgiapp.py", line 57, in load
    return self.load_wsgiapp()
           ^^^^^^^^^^^^^^^^^^^
  File "/venv/lib/python3.11/site-packages/gunicorn/app/wsgiapp.py", line 47, in load_wsgiapp
    return util.import_app(self.app_uri)
           ^^^^^^^^^^^^^^^^^^^^^^^^^^^^^
  File "/venv/lib/python3.11/site-packages/gunicorn/util.py", line 370, in import_app
    mod = importlib.import_module(module)
          ^^^^^^^^^^^^^^^^^^^^^^^^^^^^^^^
  File "/usr/lib/python3.11/importlib/__init__.py", line 126, in import_module
    return _bootstrap._gcd_import(name[level:], package, level)
           ^^^^^^^^^^^^^^^^^^^^^^^^^^^^^^^^^^^^^^^^^^^^^^^^^^^^
  File "<frozen importlib._bootstrap>", line 1204, in _gcd_import
  File "<frozen importlib._bootstrap>", line 1176, in _find_and_load
  File "<frozen importlib._bootstrap>", line 1147, in _find_and_load_unlocked
  File "<frozen importlib._bootstrap>", line 690, in _load_unlocked
  File "<frozen importlib._bootstrap_external>", line 940, in exec_module
  File "<frozen importlib._bootstrap>", line 241, in _call_with_frames_removed
  File "/app/driver.py", line 5, in <module>
    from api import create_app
  File "/app/api/__init__.py", line 7, in <module>
    from api.routes.verify_proxy import verify_bp
ModuleNotFoundError: No module named 'api.routes.verify_proxy'; 'api.routes' is not a package
[2025-05-16 17:45:13 +0000] [71] [INFO] Worker exiting (pid: 71)
[2025-05-16 17:45:13 +0000] [69] [ERROR] Worker (pid:70) exited with code 3
[2025-05-16 17:45:13 +0000] [69] [ERROR] Worker (pid:71) was sent SIGTERM!
[2025-05-16 17:45:13 +0000] [73] [ERROR] Exception in worker process
Traceback (most recent call last):
  File "/venv/lib/python3.11/site-packages/gunicorn/arbiter.py", line 608, in spawn_worker
    worker.init_process()
  File "/venv/lib/python3.11/site-packages/gunicorn/workers/ggevent.py", line 146, in init_process
    super().init_process()
  File "/venv/lib/python3.11/site-packages/gunicorn/workers/base.py", line 135, in init_process
    self.load_wsgi()
  File "/venv/lib/python3.11/site-packages/gunicorn/workers/base.py", line 147, in load_wsgi
    self.wsgi = self.app.wsgi()
                ^^^^^^^^^^^^^^^
  File "/venv/lib/python3.11/site-packages/gunicorn/app/base.py", line 66, in wsgi
    self.callable = self.load()
                    ^^^^^^^^^^^
  File "/venv/lib/python3.11/site-packages/gunicorn/app/wsgiapp.py", line 57, in load
    return self.load_wsgiapp()
           ^^^^^^^^^^^^^^^^^^^
  File "/venv/lib/python3.11/site-packages/gunicorn/app/wsgiapp.py", line 47, in load_wsgiapp
    return util.import_app(self.app_uri)
           ^^^^^^^^^^^^^^^^^^^^^^^^^^^^^
  File "/venv/lib/python3.11/site-packages/gunicorn/util.py", line 370, in import_app
    mod = importlib.import_module(module)
          ^^^^^^^^^^^^^^^^^^^^^^^^^^^^^^^
  File "/usr/lib/python3.11/importlib/__init__.py", line 126, in import_module
    return _bootstrap._gcd_import(name[level:], package, level)
           ^^^^^^^^^^^^^^^^^^^^^^^^^^^^^^^^^^^^^^^^^^^^^^^^^^^^
  File "<frozen importlib._bootstrap>", line 1204, in _gcd_import
  File "<frozen importlib._bootstrap>", line 1176, in _find_and_load
  File "<frozen importlib._bootstrap>", line 1147, in _find_and_load_unlocked
  File "<frozen importlib._bootstrap>", line 690, in _load_unlocked
  File "<frozen importlib._bootstrap_external>", line 940, in exec_module
  File "<frozen importlib._bootstrap>", line 241, in _call_with_frames_removed
  File "/app/driver.py", line 5, in <module>
    from api import create_app
  File "/app/api/__init__.py", line 7, in <module>
    from api.routes.verify_proxy import verify_bp
ModuleNotFoundError: No module named 'api.routes.verify_proxy'; 'api.routes' is not a package
[2025-05-16 17:45:13 +0000] [73] [INFO] Worker exiting (pid: 73)
[2025-05-16 17:45:13 +0000] [72] [ERROR] Exception in worker process
Traceback (most recent call last):
  File "/venv/lib/python3.11/site-packages/gunicorn/arbiter.py", line 608, in spawn_worker
    worker.init_process()
  File "/venv/lib/python3.11/site-packages/gunicorn/workers/ggevent.py", line 146, in init_process
    super().init_process()
  File "/venv/lib/python3.11/site-packages/gunicorn/workers/base.py", line 135, in init_process
    self.load_wsgi()
  File "/venv/lib/python3.11/site-packages/gunicorn/workers/base.py", line 147, in load_wsgi
    self.wsgi = self.app.wsgi()
                ^^^^^^^^^^^^^^^
  File "/venv/lib/python3.11/site-packages/gunicorn/app/base.py", line 66, in wsgi
    self.callable = self.load()
                    ^^^^^^^^^^^
  File "/venv/lib/python3.11/site-packages/gunicorn/app/wsgiapp.py", line 57, in load
    return self.load_wsgiapp()
           ^^^^^^^^^^^^^^^^^^^
  File "/venv/lib/python3.11/site-packages/gunicorn/app/wsgiapp.py", line 47, in load_wsgiapp
    return util.import_app(self.app_uri)
           ^^^^^^^^^^^^^^^^^^^^^^^^^^^^^
  File "/venv/lib/python3.11/site-packages/gunicorn/util.py", line 370, in import_app
    mod = importlib.import_module(module)
          ^^^^^^^^^^^^^^^^^^^^^^^^^^^^^^^
  File "/usr/lib/python3.11/importlib/__init__.py", line 126, in import_module
    return _bootstrap._gcd_import(name[level:], package, level)
           ^^^^^^^^^^^^^^^^^^^^^^^^^^^^^^^^^^^^^^^^^^^^^^^^^^^^
  File "<frozen importlib._bootstrap>", line 1204, in _gcd_import
  File "<frozen importlib._bootstrap>", line 1176, in _find_and_load
  File "<frozen importlib._bootstrap>", line 1147, in _find_and_load_unlocked
  File "<frozen importlib._bootstrap>", line 690, in _load_unlocked
  File "<frozen importlib._bootstrap_external>", line 940, in exec_module
  File "<frozen importlib._bootstrap>", line 241, in _call_with_frames_removed
  File "/app/driver.py", line 5, in <module>
    from api import create_app
  File "/app/api/__init__.py", line 7, in <module>
    from api.routes.verify_proxy import verify_bp
ModuleNotFoundError: No module named 'api.routes.verify_proxy'; 'api.routes' is not a package
[2025-05-16 17:45:13 +0000] [72] [INFO] Worker exiting (pid: 72)
[2025-05-16 17:45:13 +0000] [74] [ERROR] Exception in worker process
Traceback (most recent call last):
  File "/venv/lib/python3.11/site-packages/gunicorn/arbiter.py", line 608, in spawn_worker
    worker.init_process()
  File "/venv/lib/python3.11/site-packages/gunicorn/workers/ggevent.py", line 146, in init_process
    super().init_process()
  File "/venv/lib/python3.11/site-packages/gunicorn/workers/base.py", line 135, in init_process
    self.load_wsgi()
  File "/venv/lib/python3.11/site-packages/gunicorn/workers/base.py", line 147, in load_wsgi
    self.wsgi = self.app.wsgi()
                ^^^^^^^^^^^^^^^
  File "/venv/lib/python3.11/site-packages/gunicorn/app/base.py", line 66, in wsgi
    self.callable = self.load()
                    ^^^^^^^^^^^
  File "/venv/lib/python3.11/site-packages/gunicorn/app/wsgiapp.py", line 57, in load
    return self.load_wsgiapp()
           ^^^^^^^^^^^^^^^^^^^
  File "/venv/lib/python3.11/site-packages/gunicorn/app/wsgiapp.py", line 47, in load_wsgiapp
    return util.import_app(self.app_uri)
           ^^^^^^^^^^^^^^^^^^^^^^^^^^^^^
  File "/venv/lib/python3.11/site-packages/gunicorn/util.py", line 370, in import_app
    mod = importlib.import_module(module)
          ^^^^^^^^^^^^^^^^^^^^^^^^^^^^^^^
  File "/usr/lib/python3.11/importlib/__init__.py", line 126, in import_module
    return _bootstrap._gcd_import(name[level:], package, level)
           ^^^^^^^^^^^^^^^^^^^^^^^^^^^^^^^^^^^^^^^^^^^^^^^^^^^^
  File "<frozen importlib._bootstrap>", line 1204, in _gcd_import
  File "<frozen importlib._bootstrap>", line 1176, in _find_and_load
  File "<frozen importlib._bootstrap>", line 1147, in _find_and_load_unlocked
  File "<frozen importlib._bootstrap>", line 690, in _load_unlocked
  File "<frozen importlib._bootstrap_external>", line 940, in exec_module
  File "<frozen importlib._bootstrap>", line 241, in _call_with_frames_removed
  File "/app/driver.py", line 5, in <module>
    from api import create_app
  File "/app/api/__init__.py", line 7, in <module>
    from api.routes.verify_proxy import verify_bp
ModuleNotFoundError: No module named 'api.routes.verify_proxy'; 'api.routes' is not a package
[2025-05-16 17:45:13 +0000] [74] [INFO] Worker exiting (pid: 74)
[2025-05-16 17:45:14 +0000] [75] [ERROR] Exception in worker process
Traceback (most recent call last):
  File "/venv/lib/python3.11/site-packages/gunicorn/arbiter.py", line 608, in spawn_worker
    worker.init_process()
  File "/venv/lib/python3.11/site-packages/gunicorn/workers/ggevent.py", line 146, in init_process
    super().init_process()
  File "/venv/lib/python3.11/site-packages/gunicorn/workers/base.py", line 135, in init_process
    self.load_wsgi()
  File "/venv/lib/python3.11/site-packages/gunicorn/workers/base.py", line 147, in load_wsgi
    self.wsgi = self.app.wsgi()
                ^^^^^^^^^^^^^^^
  File "/venv/lib/python3.11/site-packages/gunicorn/app/base.py", line 66, in wsgi
    self.callable = self.load()
                    ^^^^^^^^^^^
  File "/venv/lib/python3.11/site-packages/gunicorn/app/wsgiapp.py", line 57, in load
    return self.load_wsgiapp()
           ^^^^^^^^^^^^^^^^^^^
  File "/venv/lib/python3.11/site-packages/gunicorn/app/wsgiapp.py", line 47, in load_wsgiapp
    return util.import_app(self.app_uri)
           ^^^^^^^^^^^^^^^^^^^^^^^^^^^^^
  File "/venv/lib/python3.11/site-packages/gunicorn/util.py", line 370, in import_app
    mod = importlib.import_module(module)
          ^^^^^^^^^^^^^^^^^^^^^^^^^^^^^^^
  File "/usr/lib/python3.11/importlib/__init__.py", line 126, in import_module
    return _bootstrap._gcd_import(name[level:], package, level)
           ^^^^^^^^^^^^^^^^^^^^^^^^^^^^^^^^^^^^^^^^^^^^^^^^^^^^
  File "<frozen importlib._bootstrap>", line 1204, in _gcd_import
  File "<frozen importlib._bootstrap>", line 1176, in _find_and_load
  File "<frozen importlib._bootstrap>", line 1147, in _find_and_load_unlocked
  File "<frozen importlib._bootstrap>", line 690, in _load_unlocked
  File "<frozen importlib._bootstrap_external>", line 940, in exec_module
  File "<frozen importlib._bootstrap>", line 241, in _call_with_frames_removed
  File "/app/driver.py", line 5, in <module>
    from api import create_app
  File "/app/api/__init__.py", line 7, in <module>
    from api.routes.verify_proxy import verify_bp
ModuleNotFoundError: No module named 'api.routes.verify_proxy'; 'api.routes' is not a package
[2025-05-16 17:45:14 +0000] [75] [INFO] Worker exiting (pid: 75)
[2025-05-16 17:45:14 +0000] [76] [ERROR] Exception in worker process
Traceback (most recent call last):
  File "/venv/lib/python3.11/site-packages/gunicorn/arbiter.py", line 608, in spawn_worker
    worker.init_process()
  File "/venv/lib/python3.11/site-packages/gunicorn/workers/ggevent.py", line 146, in init_process
    super().init_process()
  File "/venv/lib/python3.11/site-packages/gunicorn/workers/base.py", line 135, in init_process
    self.load_wsgi()
  File "/venv/lib/python3.11/site-packages/gunicorn/workers/base.py", line 147, in load_wsgi
    self.wsgi = self.app.wsgi()
                ^^^^^^^^^^^^^^^
  File "/venv/lib/python3.11/site-packages/gunicorn/app/base.py", line 66, in wsgi
    self.callable = self.load()
                    ^^^^^^^^^^^
  File "/venv/lib/python3.11/site-packages/gunicorn/app/wsgiapp.py", line 57, in load
    return self.load_wsgiapp()
           ^^^^^^^^^^^^^^^^^^^
  File "/venv/lib/python3.11/site-packages/gunicorn/app/wsgiapp.py", line 47, in load_wsgiapp
    return util.import_app(self.app_uri)
           ^^^^^^^^^^^^^^^^^^^^^^^^^^^^^
  File "/venv/lib/python3.11/site-packages/gunicorn/util.py", line 370, in import_app
    mod = importlib.import_module(module)
          ^^^^^^^^^^^^^^^^^^^^^^^^^^^^^^^
  File "/usr/lib/python3.11/importlib/__init__.py", line 126, in import_module
    return _bootstrap._gcd_import(name[level:], package, level)
           ^^^^^^^^^^^^^^^^^^^^^^^^^^^^^^^^^^^^^^^^^^^^^^^^^^^^
  File "<frozen importlib._bootstrap>", line 1204, in _gcd_import
  File "<frozen importlib._bootstrap>", line 1176, in _find_and_load
  File "<frozen importlib._bootstrap>", line 1147, in _find_and_load_unlocked
  File "<frozen importlib._bootstrap>", line 690, in _load_unlocked
  File "<frozen importlib._bootstrap_external>", line 940, in exec_module
  File "<frozen importlib._bootstrap>", line 241, in _call_with_frames_removed
  File "/app/driver.py", line 5, in <module>
    from api import create_app
  File "/app/api/__init__.py", line 7, in <module>
    from api.routes.verify_proxy import verify_bp
ModuleNotFoundError: No module named 'api.routes.verify_proxy'; 'api.routes' is not a package
[2025-05-16 17:45:14 +0000] [76] [INFO] Worker exiting (pid: 76)
[2025-05-16 17:45:14 +0000] [69] [ERROR] Worker (pid:73) exited with code 3
Traceback (most recent call last):
  File "/venv/lib/python3.11/site-packages/gunicorn/arbiter.py", line 208, in run
    self.sleep()
  File "/venv/lib/python3.11/site-packages/gunicorn/arbiter.py", line 359, in sleep
    ready = select.select([self.PIPE[0]], [], [], 1.0)
            ^^^^^^^^^^^^^^^^^^^^^^^^^^^^^^^^^^^^^^^^^^
  File "/venv/lib/python3.11/site-packages/gunicorn/arbiter.py", line 241, in handle_chld
    self.reap_workers()
  File "/venv/lib/python3.11/site-packages/gunicorn/arbiter.py", line 529, in reap_workers
    raise HaltServer(reason, self.WORKER_BOOT_ERROR)
gunicorn.errors.HaltServer: <HaltServer 'Worker failed to boot.' 3>

During handling of the above exception, another exception occurred:

Traceback (most recent call last):
  File "/venv/bin/gunicorn", line 8, in <module>
    sys.exit(run())
             ^^^^^
  File "/venv/lib/python3.11/site-packages/gunicorn/app/wsgiapp.py", line 66, in run
    WSGIApplication("%(prog)s [OPTIONS] [APP_MODULE]", prog=prog).run()
  File "/venv/lib/python3.11/site-packages/gunicorn/app/base.py", line 235, in run
    super().run()
  File "/venv/lib/python3.11/site-packages/gunicorn/app/base.py", line 71, in run
    Arbiter(self).run()
  File "/venv/lib/python3.11/site-packages/gunicorn/arbiter.py", line 228, in run
    self.halt(reason=inst.reason, exit_status=inst.exit_status)
  File "/venv/lib/python3.11/site-packages/gunicorn/arbiter.py", line 341, in halt
    self.stop()
  File "/venv/lib/python3.11/site-packages/gunicorn/arbiter.py", line 395, in stop
    time.sleep(0.1)
  File "/venv/lib/python3.11/site-packages/gunicorn/arbiter.py", line 241, in handle_chld
    self.reap_workers()
  File "/venv/lib/python3.11/site-packages/gunicorn/arbiter.py", line 529, in reap_workers
    raise HaltServer(reason, self.WORKER_BOOT_ERROR)
gunicorn.errors.HaltServer: <HaltServer 'Worker failed to boot.' 3>
[2025-05-16 17:45:14 +0000] [86] [INFO] Starting gunicorn 23.0.0
[2025-05-16 17:45:14 +0000] [86] [INFO] Listening at: https://0.0.0.0:5000 (86)
[2025-05-16 17:45:14 +0000] [86] [INFO] Using worker: gevent
[2025-05-16 17:45:14 +0000] [88] [INFO] Booting worker with pid: 88
[2025-05-16 17:45:14 +0000] [95] [INFO] Booting worker with pid: 95
[2025-05-16 17:45:14 +0000] [96] [INFO] Booting worker with pid: 96
[2025-05-16 17:45:14 +0000] [97] [INFO] Booting worker with pid: 97
[2025-05-16 17:45:14 +0000] [98] [INFO] Booting worker with pid: 98
[2025-05-16 17:45:15 +0000] [99] [INFO] Booting worker with pid: 99
[2025-05-16 17:45:15 +0000] [100] [INFO] Booting worker with pid: 100
[2025-05-16 17:45:15 +0000] [101] [INFO] Booting worker with pid: 101
[2025-05-16 17:45:15 +0000] [102] [INFO] Booting worker with pid: 102
[2025-05-16 17:45:15 +0000] [88] [ERROR] Exception in worker process
Traceback (most recent call last):
  File "/venv/lib/python3.11/site-packages/gunicorn/arbiter.py", line 608, in spawn_worker
    worker.init_process()
  File "/venv/lib/python3.11/site-packages/gunicorn/workers/ggevent.py", line 146, in init_process
    super().init_process()
  File "/venv/lib/python3.11/site-packages/gunicorn/workers/base.py", line 135, in init_process
    self.load_wsgi()
  File "/venv/lib/python3.11/site-packages/gunicorn/workers/base.py", line 147, in load_wsgi
    self.wsgi = self.app.wsgi()
                ^^^^^^^^^^^^^^^
  File "/venv/lib/python3.11/site-packages/gunicorn/app/base.py", line 66, in wsgi
    self.callable = self.load()
                    ^^^^^^^^^^^
  File "/venv/lib/python3.11/site-packages/gunicorn/app/wsgiapp.py", line 57, in load
    return self.load_wsgiapp()
           ^^^^^^^^^^^^^^^^^^^
  File "/venv/lib/python3.11/site-packages/gunicorn/app/wsgiapp.py", line 47, in load_wsgiapp
    return util.import_app(self.app_uri)
           ^^^^^^^^^^^^^^^^^^^^^^^^^^^^^
  File "/venv/lib/python3.11/site-packages/gunicorn/util.py", line 370, in import_app
    mod = importlib.import_module(module)
          ^^^^^^^^^^^^^^^^^^^^^^^^^^^^^^^
  File "/usr/lib/python3.11/importlib/__init__.py", line 126, in import_module
    return _bootstrap._gcd_import(name[level:], package, level)
           ^^^^^^^^^^^^^^^^^^^^^^^^^^^^^^^^^^^^^^^^^^^^^^^^^^^^
  File "<frozen importlib._bootstrap>", line 1204, in _gcd_import
  File "<frozen importlib._bootstrap>", line 1176, in _find_and_load
  File "<frozen importlib._bootstrap>", line 1147, in _find_and_load_unlocked
  File "<frozen importlib._bootstrap>", line 690, in _load_unlocked
  File "<frozen importlib._bootstrap_external>", line 940, in exec_module
  File "<frozen importlib._bootstrap>", line 241, in _call_with_frames_removed
  File "/app/driver.py", line 5, in <module>
    from api import create_app
  File "/app/api/__init__.py", line 7, in <module>
    from api.routes.verify_proxy import verify_bp
ModuleNotFoundError: No module named 'api.routes.verify_proxy'; 'api.routes' is not a package
[2025-05-16 17:45:15 +0000] [88] [INFO] Worker exiting (pid: 88)
[2025-05-16 17:45:15 +0000] [86] [ERROR] Worker (pid:88) exited with code 3
[2025-05-16 17:45:15 +0000] [95] [ERROR] Exception in worker process
Traceback (most recent call last):
  File "/venv/lib/python3.11/site-packages/gunicorn/arbiter.py", line 608, in spawn_worker
    worker.init_process()
  File "/venv/lib/python3.11/site-packages/gunicorn/workers/ggevent.py", line 146, in init_process
    super().init_process()
  File "/venv/lib/python3.11/site-packages/gunicorn/workers/base.py", line 135, in init_process
    self.load_wsgi()
  File "/venv/lib/python3.11/site-packages/gunicorn/workers/base.py", line 147, in load_wsgi
    self.wsgi = self.app.wsgi()
                ^^^^^^^^^^^^^^^
  File "/venv/lib/python3.11/site-packages/gunicorn/app/base.py", line 66, in wsgi
    self.callable = self.load()
                    ^^^^^^^^^^^
  File "/venv/lib/python3.11/site-packages/gunicorn/app/wsgiapp.py", line 57, in load
    return self.load_wsgiapp()
           ^^^^^^^^^^^^^^^^^^^
  File "/venv/lib/python3.11/site-packages/gunicorn/app/wsgiapp.py", line 47, in load_wsgiapp
    return util.import_app(self.app_uri)
           ^^^^^^^^^^^^^^^^^^^^^^^^^^^^^
  File "/venv/lib/python3.11/site-packages/gunicorn/util.py", line 370, in import_app
    mod = importlib.import_module(module)
          ^^^^^^^^^^^^^^^^^^^^^^^^^^^^^^^
  File "/usr/lib/python3.11/importlib/__init__.py", line 126, in import_module
    return _bootstrap._gcd_import(name[level:], package, level)
           ^^^^^^^^^^^^^^^^^^^^^^^^^^^^^^^^^^^^^^^^^^^^^^^^^^^^
  File "<frozen importlib._bootstrap>", line 1204, in _gcd_import
  File "<frozen importlib._bootstrap>", line 1176, in _find_and_load
  File "<frozen importlib._bootstrap>", line 1147, in _find_and_load_unlocked
  File "<frozen importlib._bootstrap>", line 690, in _load_unlocked
  File "<frozen importlib._bootstrap_external>", line 940, in exec_module
  File "<frozen importlib._bootstrap>", line 241, in _call_with_frames_removed
  File "/app/driver.py", line 5, in <module>
    from api import create_app
  File "/app/api/__init__.py", line 7, in <module>
    from api.routes.verify_proxy import verify_bp
ModuleNotFoundError: No module named 'api.routes.verify_proxy'; 'api.routes' is not a package
[2025-05-16 17:45:15 +0000] [95] [INFO] Worker exiting (pid: 95)
[2025-05-16 17:45:16 +0000] [96] [ERROR] Exception in worker process
Traceback (most recent call last):
  File "/venv/lib/python3.11/site-packages/gunicorn/arbiter.py", line 608, in spawn_worker
    worker.init_process()
  File "/venv/lib/python3.11/site-packages/gunicorn/workers/ggevent.py", line 146, in init_process
    super().init_process()
  File "/venv/lib/python3.11/site-packages/gunicorn/workers/base.py", line 135, in init_process
    self.load_wsgi()
  File "/venv/lib/python3.11/site-packages/gunicorn/workers/base.py", line 147, in load_wsgi
    self.wsgi = self.app.wsgi()
                ^^^^^^^^^^^^^^^
  File "/venv/lib/python3.11/site-packages/gunicorn/app/base.py", line 66, in wsgi
    self.callable = self.load()
                    ^^^^^^^^^^^
  File "/venv/lib/python3.11/site-packages/gunicorn/app/wsgiapp.py", line 57, in load
    return self.load_wsgiapp()
           ^^^^^^^^^^^^^^^^^^^
  File "/venv/lib/python3.11/site-packages/gunicorn/app/wsgiapp.py", line 47, in load_wsgiapp
    return util.import_app(self.app_uri)
           ^^^^^^^^^^^^^^^^^^^^^^^^^^^^^
  File "/venv/lib/python3.11/site-packages/gunicorn/util.py", line 370, in import_app
    mod = importlib.import_module(module)
          ^^^^^^^^^^^^^^^^^^^^^^^^^^^^^^^
  File "/usr/lib/python3.11/importlib/__init__.py", line 126, in import_module
    return _bootstrap._gcd_import(name[level:], package, level)
           ^^^^^^^^^^^^^^^^^^^^^^^^^^^^^^^^^^^^^^^^^^^^^^^^^^^^
  File "<frozen importlib._bootstrap>", line 1204, in _gcd_import
  File "<frozen importlib._bootstrap>", line 1176, in _find_and_load
  File "<frozen importlib._bootstrap>", line 1147, in _find_and_load_unlocked
  File "<frozen importlib._bootstrap>", line 690, in _load_unlocked
  File "<frozen importlib._bootstrap_external>", line 940, in exec_module
  File "<frozen importlib._bootstrap>", line 241, in _call_with_frames_removed
  File "/app/driver.py", line 5, in <module>
    from api import create_app
  File "/app/api/__init__.py", line 7, in <module>
    from api.routes.verify_proxy import verify_bp
ModuleNotFoundError: No module named 'api.routes.verify_proxy'; 'api.routes' is not a package
[2025-05-16 17:45:16 +0000] [96] [INFO] Worker exiting (pid: 96)
[2025-05-16 17:45:16 +0000] [86] [ERROR] Worker (pid:95) exited with code 3
Traceback (most recent call last):
  File "/venv/lib/python3.11/site-packages/gunicorn/arbiter.py", line 208, in run
    self.sleep()
  File "/venv/lib/python3.11/site-packages/gunicorn/arbiter.py", line 359, in sleep
    ready = select.select([self.PIPE[0]], [], [], 1.0)
            ^^^^^^^^^^^^^^^^^^^^^^^^^^^^^^^^^^^^^^^^^^
  File "/venv/lib/python3.11/site-packages/gunicorn/arbiter.py", line 241, in handle_chld
    self.reap_workers()
  File "/venv/lib/python3.11/site-packages/gunicorn/arbiter.py", line 529, in reap_workers
    raise HaltServer(reason, self.WORKER_BOOT_ERROR)
gunicorn.errors.HaltServer: <HaltServer 'Worker failed to boot.' 3>

During handling of the above exception, another exception occurred:

Traceback (most recent call last):
  File "/venv/bin/gunicorn", line 8, in <module>
    sys.exit(run())
             ^^^^^
  File "/venv/lib/python3.11/site-packages/gunicorn/app/wsgiapp.py", line 66, in run
    WSGIApplication("%(prog)s [OPTIONS] [APP_MODULE]", prog=prog).run()
  File "/venv/lib/python3.11/site-packages/gunicorn/app/base.py", line 235, in run
    super().run()
  File "/venv/lib/python3.11/site-packages/gunicorn/app/base.py", line 71, in run
    Arbiter(self).run()
  File "/venv/lib/python3.11/site-packages/gunicorn/arbiter.py", line 228, in run
    self.halt(reason=inst.reason, exit_status=inst.exit_status)
  File "/venv/lib/python3.11/site-packages/gunicorn/arbiter.py", line 341, in halt
    self.stop()
  File "/venv/lib/python3.11/site-packages/gunicorn/arbiter.py", line 395, in stop
    time.sleep(0.1)
  File "/venv/lib/python3.11/site-packages/gunicorn/arbiter.py", line 241, in handle_chld
    self.reap_workers()
  File "/venv/lib/python3.11/site-packages/gunicorn/arbiter.py", line 529, in reap_workers
    raise HaltServer(reason, self.WORKER_BOOT_ERROR)
gunicorn.errors.HaltServer: <HaltServer 'Worker failed to boot.' 3>
[2025-05-16 17:45:16 +0000] [97] [ERROR] Exception in worker process
Traceback (most recent call last):
  File "/venv/lib/python3.11/site-packages/gunicorn/arbiter.py", line 608, in spawn_worker
    worker.init_process()
  File "/venv/lib/python3.11/site-packages/gunicorn/workers/ggevent.py", line 146, in init_process
    super().init_process()
  File "/venv/lib/python3.11/site-packages/gunicorn/workers/base.py", line 135, in init_process
    self.load_wsgi()
  File "/venv/lib/python3.11/site-packages/gunicorn/workers/base.py", line 147, in load_wsgi
    self.wsgi = self.app.wsgi()
                ^^^^^^^^^^^^^^^
  File "/venv/lib/python3.11/site-packages/gunicorn/app/base.py", line 66, in wsgi
    self.callable = self.load()
                    ^^^^^^^^^^^
  File "/venv/lib/python3.11/site-packages/gunicorn/app/wsgiapp.py", line 57, in load
    return self.load_wsgiapp()
           ^^^^^^^^^^^^^^^^^^^
  File "/venv/lib/python3.11/site-packages/gunicorn/app/wsgiapp.py", line 47, in load_wsgiapp
    return util.import_app(self.app_uri)
           ^^^^^^^^^^^^^^^^^^^^^^^^^^^^^
  File "/venv/lib/python3.11/site-packages/gunicorn/util.py", line 370, in import_app
    mod = importlib.import_module(module)
          ^^^^^^^^^^^^^^^^^^^^^^^^^^^^^^^
  File "/usr/lib/python3.11/importlib/__init__.py", line 126, in import_module
    return _bootstrap._gcd_import(name[level:], package, level)
           ^^^^^^^^^^^^^^^^^^^^^^^^^^^^^^^^^^^^^^^^^^^^^^^^^^^^
  File "<frozen importlib._bootstrap>", line 1204, in _gcd_import
  File "<frozen importlib._bootstrap>", line 1176, in _find_and_load
  File "<frozen importlib._bootstrap>", line 1147, in _find_and_load_unlocked
  File "<frozen importlib._bootstrap>", line 690, in _load_unlocked
  File "<frozen importlib._bootstrap_external>", line 940, in exec_module
  File "<frozen importlib._bootstrap>", line 241, in _call_with_frames_removed
  File "/app/driver.py", line 5, in <module>
    from api import create_app
  File "/app/api/__init__.py", line 7, in <module>
    from api.routes.verify_proxy import verify_bp
ModuleNotFoundError: No module named 'api.routes.verify_proxy'; 'api.routes' is not a package
[2025-05-16 17:45:17 +0000] [109] [INFO] Starting gunicorn 23.0.0
[2025-05-16 17:45:17 +0000] [109] [INFO] Listening at: https://0.0.0.0:5000 (109)
[2025-05-16 17:45:17 +0000] [109] [INFO] Using worker: gevent
[2025-05-16 17:45:17 +0000] [111] [INFO] Booting worker with pid: 111
[2025-05-16 17:45:17 +0000] [112] [INFO] Booting worker with pid: 112
[2025-05-16 17:45:17 +0000] [113] [INFO] Booting worker with pid: 113
[2025-05-16 17:45:17 +0000] [114] [INFO] Booting worker with pid: 114
[2025-05-16 17:45:17 +0000] [115] [INFO] Booting worker with pid: 115
[2025-05-16 17:45:17 +0000] [116] [INFO] Booting worker with pid: 116
[2025-05-16 17:45:17 +0000] [118] [INFO] Booting worker with pid: 118
[2025-05-16 17:45:17 +0000] [125] [INFO] Booting worker with pid: 125
[2025-05-16 17:45:17 +0000] [126] [INFO] Booting worker with pid: 126
[2025-05-16 17:45:18 +0000] [111] [ERROR] Exception in worker process
Traceback (most recent call last):
  File "/venv/lib/python3.11/site-packages/gunicorn/arbiter.py", line 608, in spawn_worker
    worker.init_process()
  File "/venv/lib/python3.11/site-packages/gunicorn/workers/ggevent.py", line 146, in init_process
    super().init_process()
  File "/venv/lib/python3.11/site-packages/gunicorn/workers/base.py", line 135, in init_process
    self.load_wsgi()
  File "/venv/lib/python3.11/site-packages/gunicorn/workers/base.py", line 147, in load_wsgi
    self.wsgi = self.app.wsgi()
                ^^^^^^^^^^^^^^^
  File "/venv/lib/python3.11/site-packages/gunicorn/app/base.py", line 66, in wsgi
    self.callable = self.load()
                    ^^^^^^^^^^^
  File "/venv/lib/python3.11/site-packages/gunicorn/app/wsgiapp.py", line 57, in load
    return self.load_wsgiapp()
           ^^^^^^^^^^^^^^^^^^^
  File "/venv/lib/python3.11/site-packages/gunicorn/app/wsgiapp.py", line 47, in load_wsgiapp
    return util.import_app(self.app_uri)
           ^^^^^^^^^^^^^^^^^^^^^^^^^^^^^
  File "/venv/lib/python3.11/site-packages/gunicorn/util.py", line 370, in import_app
    mod = importlib.import_module(module)
          ^^^^^^^^^^^^^^^^^^^^^^^^^^^^^^^
  File "/usr/lib/python3.11/importlib/__init__.py", line 126, in import_module
    return _bootstrap._gcd_import(name[level:], package, level)
           ^^^^^^^^^^^^^^^^^^^^^^^^^^^^^^^^^^^^^^^^^^^^^^^^^^^^
  File "<frozen importlib._bootstrap>", line 1204, in _gcd_import
  File "<frozen importlib._bootstrap>", line 1176, in _find_and_load
  File "<frozen importlib._bootstrap>", line 1147, in _find_and_load_unlocked
  File "<frozen importlib._bootstrap>", line 690, in _load_unlocked
  File "<frozen importlib._bootstrap_external>", line 940, in exec_module
  File "<frozen importlib._bootstrap>", line 241, in _call_with_frames_removed
  File "/app/driver.py", line 5, in <module>
    from api import create_app
  File "/app/api/__init__.py", line 7, in <module>
    from api.routes.verify_proxy import verify_bp
ModuleNotFoundError: No module named 'api.routes.verify_proxy'; 'api.routes' is not a package
[2025-05-16 17:45:18 +0000] [111] [INFO] Worker exiting (pid: 111)
[2025-05-16 17:45:18 +0000] [109] [ERROR] Worker (pid:111) exited with code 3
[2025-05-16 17:45:18 +0000] [112] [ERROR] Exception in worker process
Traceback (most recent call last):
  File "/venv/lib/python3.11/site-packages/gunicorn/arbiter.py", line 608, in spawn_worker
    worker.init_process()
  File "/venv/lib/python3.11/site-packages/gunicorn/workers/ggevent.py", line 146, in init_process
    super().init_process()
  File "/venv/lib/python3.11/site-packages/gunicorn/workers/base.py", line 135, in init_process
    self.load_wsgi()
  File "/venv/lib/python3.11/site-packages/gunicorn/workers/base.py", line 147, in load_wsgi
    self.wsgi = self.app.wsgi()
                ^^^^^^^^^^^^^^^
  File "/venv/lib/python3.11/site-packages/gunicorn/app/base.py", line 66, in wsgi
    self.callable = self.load()
                    ^^^^^^^^^^^
  File "/venv/lib/python3.11/site-packages/gunicorn/app/wsgiapp.py", line 57, in load
    return self.load_wsgiapp()
           ^^^^^^^^^^^^^^^^^^^
  File "/venv/lib/python3.11/site-packages/gunicorn/app/wsgiapp.py", line 47, in load_wsgiapp
    return util.import_app(self.app_uri)
           ^^^^^^^^^^^^^^^^^^^^^^^^^^^^^
  File "/venv/lib/python3.11/site-packages/gunicorn/util.py", line 370, in import_app
    mod = importlib.import_module(module)
          ^^^^^^^^^^^^^^^^^^^^^^^^^^^^^^^
  File "/usr/lib/python3.11/importlib/__init__.py", line 126, in import_module
    return _bootstrap._gcd_import(name[level:], package, level)
           ^^^^^^^^^^^^^^^^^^^^^^^^^^^^^^^^^^^^^^^^^^^^^^^^^^^^
  File "<frozen importlib._bootstrap>", line 1204, in _gcd_import
  File "<frozen importlib._bootstrap>", line 1176, in _find_and_load
  File "<frozen importlib._bootstrap>", line 1147, in _find_and_load_unlocked
  File "<frozen importlib._bootstrap>", line 690, in _load_unlocked
  File "<frozen importlib._bootstrap_external>", line 940, in exec_module
  File "<frozen importlib._bootstrap>", line 241, in _call_with_frames_removed
  File "/app/driver.py", line 5, in <module>
    from api import create_app
  File "/app/api/__init__.py", line 7, in <module>
    from api.routes.verify_proxy import verify_bp
ModuleNotFoundError: No module named 'api.routes.verify_proxy'; 'api.routes' is not a package
[2025-05-16 17:45:18 +0000] [112] [INFO] Worker exiting (pid: 112)
[2025-05-16 17:45:18 +0000] [113] [ERROR] Exception in worker process
Traceback (most recent call last):
  File "/venv/lib/python3.11/site-packages/gunicorn/arbiter.py", line 608, in spawn_worker
    worker.init_process()
  File "/venv/lib/python3.11/site-packages/gunicorn/workers/ggevent.py", line 146, in init_process
    super().init_process()
  File "/venv/lib/python3.11/site-packages/gunicorn/workers/base.py", line 135, in init_process
    self.load_wsgi()
  File "/venv/lib/python3.11/site-packages/gunicorn/workers/base.py", line 147, in load_wsgi
    self.wsgi = self.app.wsgi()
                ^^^^^^^^^^^^^^^
  File "/venv/lib/python3.11/site-packages/gunicorn/app/base.py", line 66, in wsgi
    self.callable = self.load()
                    ^^^^^^^^^^^
  File "/venv/lib/python3.11/site-packages/gunicorn/app/wsgiapp.py", line 57, in load
    return self.load_wsgiapp()
           ^^^^^^^^^^^^^^^^^^^
  File "/venv/lib/python3.11/site-packages/gunicorn/app/wsgiapp.py", line 47, in load_wsgiapp
    return util.import_app(self.app_uri)
           ^^^^^^^^^^^^^^^^^^^^^^^^^^^^^
  File "/venv/lib/python3.11/site-packages/gunicorn/util.py", line 370, in import_app
    mod = importlib.import_module(module)
          ^^^^^^^^^^^^^^^^^^^^^^^^^^^^^^^
  File "/usr/lib/python3.11/importlib/__init__.py", line 126, in import_module
    return _bootstrap._gcd_import(name[level:], package, level)
           ^^^^^^^^^^^^^^^^^^^^^^^^^^^^^^^^^^^^^^^^^^^^^^^^^^^^
  File "<frozen importlib._bootstrap>", line 1204, in _gcd_import
  File "<frozen importlib._bootstrap>", line 1176, in _find_and_load
  File "<frozen importlib._bootstrap>", line 1147, in _find_and_load_unlocked
  File "<frozen importlib._bootstrap>", line 690, in _load_unlocked
  File "<frozen importlib._bootstrap_external>", line 940, in exec_module
  File "<frozen importlib._bootstrap>", line 241, in _call_with_frames_removed
  File "/app/driver.py", line 5, in <module>
    from api import create_app
  File "/app/api/__init__.py", line 7, in <module>
    from api.routes.verify_proxy import verify_bp
ModuleNotFoundError: No module named 'api.routes.verify_proxy'; 'api.routes' is not a package
[2025-05-16 17:45:18 +0000] [113] [INFO] Worker exiting (pid: 113)
[2025-05-16 17:45:18 +0000] [114] [ERROR] Exception in worker process
Traceback (most recent call last):
  File "/venv/lib/python3.11/site-packages/gunicorn/arbiter.py", line 608, in spawn_worker
    worker.init_process()
  File "/venv/lib/python3.11/site-packages/gunicorn/workers/ggevent.py", line 146, in init_process
    super().init_process()
  File "/venv/lib/python3.11/site-packages/gunicorn/workers/base.py", line 135, in init_process
    self.load_wsgi()
  File "/venv/lib/python3.11/site-packages/gunicorn/workers/base.py", line 147, in load_wsgi
    self.wsgi = self.app.wsgi()
                ^^^^^^^^^^^^^^^
  File "/venv/lib/python3.11/site-packages/gunicorn/app/base.py", line 66, in wsgi
    self.callable = self.load()
                    ^^^^^^^^^^^
  File "/venv/lib/python3.11/site-packages/gunicorn/app/wsgiapp.py", line 57, in load
    return self.load_wsgiapp()
           ^^^^^^^^^^^^^^^^^^^
  File "/venv/lib/python3.11/site-packages/gunicorn/app/wsgiapp.py", line 47, in load_wsgiapp
    return util.import_app(self.app_uri)
           ^^^^^^^^^^^^^^^^^^^^^^^^^^^^^
  File "/venv/lib/python3.11/site-packages/gunicorn/util.py", line 370, in import_app
    mod = importlib.import_module(module)
          ^^^^^^^^^^^^^^^^^^^^^^^^^^^^^^^
  File "/usr/lib/python3.11/importlib/__init__.py", line 126, in import_module
    return _bootstrap._gcd_import(name[level:], package, level)
           ^^^^^^^^^^^^^^^^^^^^^^^^^^^^^^^^^^^^^^^^^^^^^^^^^^^^
  File "<frozen importlib._bootstrap>", line 1204, in _gcd_import
  File "<frozen importlib._bootstrap>", line 1176, in _find_and_load
  File "<frozen importlib._bootstrap>", line 1147, in _find_and_load_unlocked
  File "<frozen importlib._bootstrap>", line 690, in _load_unlocked
  File "<frozen importlib._bootstrap_external>", line 940, in exec_module
  File "<frozen importlib._bootstrap>", line 241, in _call_with_frames_removed
  File "/app/driver.py", line 5, in <module>
    from api import create_app
  File "/app/api/__init__.py", line 7, in <module>
    from api.routes.verify_proxy import verify_bp
ModuleNotFoundError: No module named 'api.routes.verify_proxy'; 'api.routes' is not a package
[2025-05-16 17:45:18 +0000] [114] [INFO] Worker exiting (pid: 114)
[2025-05-16 17:45:19 +0000] [116] [ERROR] Exception in worker process
Traceback (most recent call last):
  File "/venv/lib/python3.11/site-packages/gunicorn/arbiter.py", line 608, in spawn_worker
    worker.init_process()
  File "/venv/lib/python3.11/site-packages/gunicorn/workers/ggevent.py", line 146, in init_process
    super().init_process()
  File "/venv/lib/python3.11/site-packages/gunicorn/workers/base.py", line 135, in init_process
    self.load_wsgi()
  File "/venv/lib/python3.11/site-packages/gunicorn/workers/base.py", line 147, in load_wsgi
    self.wsgi = self.app.wsgi()
                ^^^^^^^^^^^^^^^
  File "/venv/lib/python3.11/site-packages/gunicorn/app/base.py", line 66, in wsgi
    self.callable = self.load()
                    ^^^^^^^^^^^
  File "/venv/lib/python3.11/site-packages/gunicorn/app/wsgiapp.py", line 57, in load
    return self.load_wsgiapp()
           ^^^^^^^^^^^^^^^^^^^
  File "/venv/lib/python3.11/site-packages/gunicorn/app/wsgiapp.py", line 47, in load_wsgiapp
    return util.import_app(self.app_uri)
           ^^^^^^^^^^^^^^^^^^^^^^^^^^^^^
  File "/venv/lib/python3.11/site-packages/gunicorn/util.py", line 370, in import_app
    mod = importlib.import_module(module)
          ^^^^^^^^^^^^^^^^^^^^^^^^^^^^^^^
  File "/usr/lib/python3.11/importlib/__init__.py", line 126, in import_module
    return _bootstrap._gcd_import(name[level:], package, level)
           ^^^^^^^^^^^^^^^^^^^^^^^^^^^^^^^^^^^^^^^^^^^^^^^^^^^^
  File "<frozen importlib._bootstrap>", line 1204, in _gcd_import
  File "<frozen importlib._bootstrap>", line 1176, in _find_and_load
  File "<frozen importlib._bootstrap>", line 1147, in _find_and_load_unlocked
  File "<frozen importlib._bootstrap>", line 690, in _load_unlocked
  File "<frozen importlib._bootstrap_external>", line 940, in exec_module
  File "<frozen importlib._bootstrap>", line 241, in _call_with_frames_removed
  File "/app/driver.py", line 5, in <module>
    from api import create_app
  File "/app/api/__init__.py", line 7, in <module>
    from api.routes.verify_proxy import verify_bp
ModuleNotFoundError: No module named 'api.routes.verify_proxy'; 'api.routes' is not a package
[2025-05-16 17:45:19 +0000] [116] [INFO] Worker exiting (pid: 116)
[2025-05-16 17:45:19 +0000] [109] [ERROR] Worker (pid:112) exited with code 3
Traceback (most recent call last):
  File "/venv/lib/python3.11/site-packages/gunicorn/arbiter.py", line 208, in run
    self.sleep()
  File "/venv/lib/python3.11/site-packages/gunicorn/arbiter.py", line 359, in sleep
    ready = select.select([self.PIPE[0]], [], [], 1.0)
            ^^^^^^^^^^^^^^^^^^^^^^^^^^^^^^^^^^^^^^^^^^
  File "/venv/lib/python3.11/site-packages/gunicorn/arbiter.py", line 241, in handle_chld
    self.reap_workers()
  File "/venv/lib/python3.11/site-packages/gunicorn/arbiter.py", line 529, in reap_workers
    raise HaltServer(reason, self.WORKER_BOOT_ERROR)
gunicorn.errors.HaltServer: <HaltServer 'Worker failed to boot.' 3>

During handling of the above exception, another exception occurred:

Traceback (most recent call last):
  File "/venv/bin/gunicorn", line 8, in <module>
    sys.exit(run())
             ^^^^^
  File "/venv/lib/python3.11/site-packages/gunicorn/app/wsgiapp.py", line 66, in run
    WSGIApplication("%(prog)s [OPTIONS] [APP_MODULE]", prog=prog).run()
  File "/venv/lib/python3.11/site-packages/gunicorn/app/base.py", line 235, in run
    super().run()
  File "/venv/lib/python3.11/site-packages/gunicorn/app/base.py", line 71, in run
    Arbiter(self).run()
  File "/venv/lib/python3.11/site-packages/gunicorn/arbiter.py", line 228, in run
    self.halt(reason=inst.reason, exit_status=inst.exit_status)
  File "/venv/lib/python3.11/site-packages/gunicorn/arbiter.py", line 341, in halt
    self.stop()
  File "/venv/lib/python3.11/site-packages/gunicorn/arbiter.py", line 395, in stop
    time.sleep(0.1)
  File "/venv/lib/python3.11/site-packages/gunicorn/arbiter.py", line 241, in handle_chld
    self.reap_workers()
  File "/venv/lib/python3.11/site-packages/gunicorn/arbiter.py", line 529, in reap_workers
    raise HaltServer(reason, self.WORKER_BOOT_ERROR)
gunicorn.errors.HaltServer: <HaltServer 'Worker failed to boot.' 3>
[2025-05-16 17:45:19 +0000] [115] [ERROR] Exception in worker process
Traceback (most recent call last):
  File "/venv/lib/python3.11/site-packages/gunicorn/arbiter.py", line 608, in spawn_worker
    worker.init_process()
  File "/venv/lib/python3.11/site-packages/gunicorn/workers/ggevent.py", line 146, in init_process
    super().init_process()
  File "/venv/lib/python3.11/site-packages/gunicorn/workers/base.py", line 135, in init_process
    self.load_wsgi()
  File "/venv/lib/python3.11/site-packages/gunicorn/workers/base.py", line 147, in load_wsgi
    self.wsgi = self.app.wsgi()
                ^^^^^^^^^^^^^^^
  File "/venv/lib/python3.11/site-packages/gunicorn/app/base.py", line 66, in wsgi
    self.callable = self.load()
                    ^^^^^^^^^^^
  File "/venv/lib/python3.11/site-packages/gunicorn/app/wsgiapp.py", line 57, in load
    return self.load_wsgiapp()
           ^^^^^^^^^^^^^^^^^^^
  File "/venv/lib/python3.11/site-packages/gunicorn/app/wsgiapp.py", line 47, in load_wsgiapp
    return util.import_app(self.app_uri)
           ^^^^^^^^^^^^^^^^^^^^^^^^^^^^^
  File "/venv/lib/python3.11/site-packages/gunicorn/util.py", line 370, in import_app
    mod = importlib.import_module(module)
          ^^^^^^^^^^^^^^^^^^^^^^^^^^^^^^^
  File "/usr/lib/python3.11/importlib/__init__.py", line 126, in import_module
    return _bootstrap._gcd_import(name[level:], package, level)
           ^^^^^^^^^^^^^^^^^^^^^^^^^^^^^^^^^^^^^^^^^^^^^^^^^^^^
  File "<frozen importlib._bootstrap>", line 1204, in _gcd_import
  File "<frozen importlib._bootstrap>", line 1176, in _find_and_load
  File "<frozen importlib._bootstrap>", line 1147, in _find_and_load_unlocked
  File "<frozen importlib._bootstrap>", line 690, in _load_unlocked
  File "<frozen importlib._bootstrap_external>", line 940, in exec_module
  File "<frozen importlib._bootstrap>", line 241, in _call_with_frames_removed
  File "/app/driver.py", line 5, in <module>
    from api import create_app
  File "/app/api/__init__.py", line 7, in <module>
    from api.routes.verify_proxy import verify_bp
ModuleNotFoundError: No module named 'api.routes.verify_proxy'; 'api.routes' is not a package
[2025-05-16 17:45:19 +0000] [115] [INFO] Worker exiting (pid: 115)
[2025-05-16 17:45:19 +0000] [118] [ERROR] Exception in worker process
Traceback (most recent call last):
  File "/venv/lib/python3.11/site-packages/gunicorn/arbiter.py", line 608, in spawn_worker
    worker.init_process()
  File "/venv/lib/python3.11/site-packages/gunicorn/workers/ggevent.py", line 146, in init_process
    super().init_process()
  File "/venv/lib/python3.11/site-packages/gunicorn/workers/base.py", line 135, in init_process
    self.load_wsgi()
  File "/venv/lib/python3.11/site-packages/gunicorn/workers/base.py", line 147, in load_wsgi
    self.wsgi = self.app.wsgi()
                ^^^^^^^^^^^^^^^
  File "/venv/lib/python3.11/site-packages/gunicorn/app/base.py", line 66, in wsgi
    self.callable = self.load()
                    ^^^^^^^^^^^
  File "/venv/lib/python3.11/site-packages/gunicorn/app/wsgiapp.py", line 57, in load
    return self.load_wsgiapp()
           ^^^^^^^^^^^^^^^^^^^
  File "/venv/lib/python3.11/site-packages/gunicorn/app/wsgiapp.py", line 47, in load_wsgiapp
    return util.import_app(self.app_uri)
           ^^^^^^^^^^^^^^^^^^^^^^^^^^^^^
  File "/venv/lib/python3.11/site-packages/gunicorn/util.py", line 370, in import_app
    mod = importlib.import_module(module)
          ^^^^^^^^^^^^^^^^^^^^^^^^^^^^^^^
  File "/usr/lib/python3.11/importlib/__init__.py", line 126, in import_module
    return _bootstrap._gcd_import(name[level:], package, level)
           ^^^^^^^^^^^^^^^^^^^^^^^^^^^^^^^^^^^^^^^^^^^^^^^^^^^^
  File "<frozen importlib._bootstrap>", line 1204, in _gcd_import
  File "<frozen importlib._bootstrap>", line 1176, in _find_and_load
  File "<frozen importlib._bootstrap>", line 1147, in _find_and_load_unlocked
  File "<frozen importlib._bootstrap>", line 690, in _load_unlocked
  File "<frozen importlib._bootstrap_external>", line 940, in exec_module
  File "<frozen importlib._bootstrap>", line 241, in _call_with_frames_removed
  File "/app/driver.py", line 5, in <module>
    from api import create_app
  File "/app/api/__init__.py", line 7, in <module>
    from api.routes.verify_proxy import verify_bp
ModuleNotFoundError: No module named 'api.routes.verify_proxy'; 'api.routes' is not a package
[2025-05-16 17:45:19 +0000] [118] [INFO] Worker exiting (pid: 118)
[2025-05-16 17:45:19 +0000] [125] [ERROR] Exception in worker process
Traceback (most recent call last):
  File "/venv/lib/python3.11/site-packages/gunicorn/arbiter.py", line 608, in spawn_worker
    worker.init_process()
  File "/venv/lib/python3.11/site-packages/gunicorn/workers/ggevent.py", line 146, in init_process
    super().init_process()
  File "/venv/lib/python3.11/site-packages/gunicorn/workers/base.py", line 135, in init_process
    self.load_wsgi()
  File "/venv/lib/python3.11/site-packages/gunicorn/workers/base.py", line 147, in load_wsgi
    self.wsgi = self.app.wsgi()
                ^^^^^^^^^^^^^^^
  File "/venv/lib/python3.11/site-packages/gunicorn/app/base.py", line 66, in wsgi
    self.callable = self.load()
                    ^^^^^^^^^^^
  File "/venv/lib/python3.11/site-packages/gunicorn/app/wsgiapp.py", line 57, in load
    return self.load_wsgiapp()
           ^^^^^^^^^^^^^^^^^^^
  File "/venv/lib/python3.11/site-packages/gunicorn/app/wsgiapp.py", line 47, in load_wsgiapp
    return util.import_app(self.app_uri)
           ^^^^^^^^^^^^^^^^^^^^^^^^^^^^^
  File "/venv/lib/python3.11/site-packages/gunicorn/util.py", line 370, in import_app
    mod = importlib.import_module(module)
          ^^^^^^^^^^^^^^^^^^^^^^^^^^^^^^^
  File "/usr/lib/python3.11/importlib/__init__.py", line 126, in import_module
    return _bootstrap._gcd_import(name[level:], package, level)
           ^^^^^^^^^^^^^^^^^^^^^^^^^^^^^^^^^^^^^^^^^^^^^^^^^^^^
  File "<frozen importlib._bootstrap>", line 1204, in _gcd_import
  File "<frozen importlib._bootstrap>", line 1176, in _find_and_load
  File "<frozen importlib._bootstrap>", line 1147, in _find_and_load_unlocked
  File "<frozen importlib._bootstrap>", line 690, in _load_unlocked
  File "<frozen importlib._bootstrap_external>", line 940, in exec_module
  File "<frozen importlib._bootstrap>", line 241, in _call_with_frames_removed
  File "/app/driver.py", line 5, in <module>
    from api import create_app
  File "/app/api/__init__.py", line 7, in <module>
    from api.routes.verify_proxy import verify_bp
ModuleNotFoundError: No module named 'api.routes.verify_proxy'; 'api.routes' is not a package
[2025-05-16 17:45:19 +0000] [125] [INFO] Worker exiting (pid: 125)
[2025-05-16 17:45:19 +0000] [126] [ERROR] Exception in worker process
Traceback (most recent call last):
  File "/venv/lib/python3.11/site-packages/gunicorn/arbiter.py", line 608, in spawn_worker
    worker.init_process()
  File "/venv/lib/python3.11/site-packages/gunicorn/workers/ggevent.py", line 146, in init_process
    super().init_process()
  File "/venv/lib/python3.11/site-packages/gunicorn/workers/base.py", line 135, in init_process
    self.load_wsgi()
  File "/venv/lib/python3.11/site-packages/gunicorn/workers/base.py", line 147, in load_wsgi
    self.wsgi = self.app.wsgi()
                ^^^^^^^^^^^^^^^
  File "/venv/lib/python3.11/site-packages/gunicorn/app/base.py", line 66, in wsgi
    self.callable = self.load()
                    ^^^^^^^^^^^
  File "/venv/lib/python3.11/site-packages/gunicorn/app/wsgiapp.py", line 57, in load
    return self.load_wsgiapp()
           ^^^^^^^^^^^^^^^^^^^
  File "/venv/lib/python3.11/site-packages/gunicorn/app/wsgiapp.py", line 47, in load_wsgiapp
    return util.import_app(self.app_uri)
           ^^^^^^^^^^^^^^^^^^^^^^^^^^^^^
  File "/venv/lib/python3.11/site-packages/gunicorn/util.py", line 370, in import_app
    mod = importlib.import_module(module)
          ^^^^^^^^^^^^^^^^^^^^^^^^^^^^^^^
  File "/usr/lib/python3.11/importlib/__init__.py", line 126, in import_module
    return _bootstrap._gcd_import(name[level:], package, level)
           ^^^^^^^^^^^^^^^^^^^^^^^^^^^^^^^^^^^^^^^^^^^^^^^^^^^^
  File "<frozen importlib._bootstrap>", line 1204, in _gcd_import
  File "<frozen importlib._bootstrap>", line 1176, in _find_and_load
  File "<frozen importlib._bootstrap>", line 1147, in _find_and_load_unlocked
  File "<frozen importlib._bootstrap>", line 690, in _load_unlocked
  File "<frozen importlib._bootstrap_external>", line 940, in exec_module
  File "<frozen importlib._bootstrap>", line 241, in _call_with_frames_removed
  File "/app/driver.py", line 5, in <module>
    from api import create_app
  File "/app/api/__init__.py", line 7, in <module>
    from api.routes.verify_proxy import verify_bp
ModuleNotFoundError: No module named 'api.routes.verify_proxy'; 'api.routes' is not a package
[2025-05-16 17:45:19 +0000] [126] [INFO] Worker exiting (pid: 126)
[2025-05-16 17:45:19 +0000] [134] [INFO] Starting gunicorn 23.0.0
[2025-05-16 17:45:19 +0000] [134] [INFO] Listening at: https://0.0.0.0:5000 (134)
[2025-05-16 17:45:19 +0000] [134] [INFO] Using worker: gevent
[2025-05-16 17:45:19 +0000] [135] [INFO] Booting worker with pid: 135
[2025-05-16 17:45:19 +0000] [136] [INFO] Booting worker with pid: 136
[2025-05-16 17:45:19 +0000] [137] [INFO] Booting worker with pid: 137
[2025-05-16 17:45:19 +0000] [138] [INFO] Booting worker with pid: 138
[2025-05-16 17:45:19 +0000] [139] [INFO] Booting worker with pid: 139
[2025-05-16 17:45:19 +0000] [140] [INFO] Booting worker with pid: 140
[2025-05-16 17:45:19 +0000] [141] [INFO] Booting worker with pid: 141
[2025-05-16 17:45:20 +0000] [142] [INFO] Booting worker with pid: 142
[2025-05-16 17:45:20 +0000] [143] [INFO] Booting worker with pid: 143
[2025-05-16 17:45:20 +0000] [135] [ERROR] Exception in worker process
Traceback (most recent call last):
  File "/venv/lib/python3.11/site-packages/gunicorn/arbiter.py", line 608, in spawn_worker
    worker.init_process()
  File "/venv/lib/python3.11/site-packages/gunicorn/workers/ggevent.py", line 146, in init_process
    super().init_process()
  File "/venv/lib/python3.11/site-packages/gunicorn/workers/base.py", line 135, in init_process
    self.load_wsgi()
  File "/venv/lib/python3.11/site-packages/gunicorn/workers/base.py", line 147, in load_wsgi
    self.wsgi = self.app.wsgi()
                ^^^^^^^^^^^^^^^
  File "/venv/lib/python3.11/site-packages/gunicorn/app/base.py", line 66, in wsgi
    self.callable = self.load()
                    ^^^^^^^^^^^
  File "/venv/lib/python3.11/site-packages/gunicorn/app/wsgiapp.py", line 57, in load
    return self.load_wsgiapp()
           ^^^^^^^^^^^^^^^^^^^
  File "/venv/lib/python3.11/site-packages/gunicorn/app/wsgiapp.py", line 47, in load_wsgiapp
    return util.import_app(self.app_uri)
           ^^^^^^^^^^^^^^^^^^^^^^^^^^^^^
  File "/venv/lib/python3.11/site-packages/gunicorn/util.py", line 370, in import_app
    mod = importlib.import_module(module)
          ^^^^^^^^^^^^^^^^^^^^^^^^^^^^^^^
  File "/usr/lib/python3.11/importlib/__init__.py", line 126, in import_module
    return _bootstrap._gcd_import(name[level:], package, level)
           ^^^^^^^^^^^^^^^^^^^^^^^^^^^^^^^^^^^^^^^^^^^^^^^^^^^^
  File "<frozen importlib._bootstrap>", line 1204, in _gcd_import
  File "<frozen importlib._bootstrap>", line 1176, in _find_and_load
  File "<frozen importlib._bootstrap>", line 1147, in _find_and_load_unlocked
  File "<frozen importlib._bootstrap>", line 690, in _load_unlocked
  File "<frozen importlib._bootstrap_external>", line 940, in exec_module
  File "<frozen importlib._bootstrap>", line 241, in _call_with_frames_removed
  File "/app/driver.py", line 5, in <module>
    from api import create_app
  File "/app/api/__init__.py", line 7, in <module>
    from api.routes.verify_proxy import verify_bp
ModuleNotFoundError: No module named 'api.routes.verify_proxy'; 'api.routes' is not a package
[2025-05-16 17:45:20 +0000] [135] [INFO] Worker exiting (pid: 135)
[2025-05-16 17:45:20 +0000] [136] [ERROR] Exception in worker process
Traceback (most recent call last):
  File "/venv/lib/python3.11/site-packages/gunicorn/arbiter.py", line 608, in spawn_worker
    worker.init_process()
  File "/venv/lib/python3.11/site-packages/gunicorn/workers/ggevent.py", line 146, in init_process
    super().init_process()
  File "/venv/lib/python3.11/site-packages/gunicorn/workers/base.py", line 135, in init_process
    self.load_wsgi()
  File "/venv/lib/python3.11/site-packages/gunicorn/workers/base.py", line 147, in load_wsgi
    self.wsgi = self.app.wsgi()
                ^^^^^^^^^^^^^^^
  File "/venv/lib/python3.11/site-packages/gunicorn/app/base.py", line 66, in wsgi
    self.callable = self.load()
                    ^^^^^^^^^^^
  File "/venv/lib/python3.11/site-packages/gunicorn/app/wsgiapp.py", line 57, in load
    return self.load_wsgiapp()
           ^^^^^^^^^^^^^^^^^^^
  File "/venv/lib/python3.11/site-packages/gunicorn/app/wsgiapp.py", line 47, in load_wsgiapp
    return util.import_app(self.app_uri)
           ^^^^^^^^^^^^^^^^^^^^^^^^^^^^^
  File "/venv/lib/python3.11/site-packages/gunicorn/util.py", line 370, in import_app
    mod = importlib.import_module(module)
          ^^^^^^^^^^^^^^^^^^^^^^^^^^^^^^^
  File "/usr/lib/python3.11/importlib/__init__.py", line 126, in import_module
    return _bootstrap._gcd_import(name[level:], package, level)
           ^^^^^^^^^^^^^^^^^^^^^^^^^^^^^^^^^^^^^^^^^^^^^^^^^^^^
  File "<frozen importlib._bootstrap>", line 1204, in _gcd_import
  File "<frozen importlib._bootstrap>", line 1176, in _find_and_load
  File "<frozen importlib._bootstrap>", line 1147, in _find_and_load_unlocked
  File "<frozen importlib._bootstrap>", line 690, in _load_unlocked
  File "<frozen importlib._bootstrap_external>", line 940, in exec_module
  File "<frozen importlib._bootstrap>", line 241, in _call_with_frames_removed
  File "/app/driver.py", line 5, in <module>
    from api import create_app
  File "/app/api/__init__.py", line 7, in <module>
    from api.routes.verify_proxy import verify_bp
ModuleNotFoundError: No module named 'api.routes.verify_proxy'; 'api.routes' is not a package
[2025-05-16 17:45:20 +0000] [136] [INFO] Worker exiting (pid: 136)
[2025-05-16 17:45:21 +0000] [134] [ERROR] Worker (pid:135) exited with code 3
[2025-05-16 17:45:21 +0000] [134] [ERROR] Worker (pid:136) was sent SIGTERM!
[2025-05-16 17:45:21 +0000] [137] [ERROR] Exception in worker process
Traceback (most recent call last):
  File "/venv/lib/python3.11/site-packages/gunicorn/arbiter.py", line 608, in spawn_worker
    worker.init_process()
  File "/venv/lib/python3.11/site-packages/gunicorn/workers/ggevent.py", line 146, in init_process
    super().init_process()
  File "/venv/lib/python3.11/site-packages/gunicorn/workers/base.py", line 135, in init_process
    self.load_wsgi()
  File "/venv/lib/python3.11/site-packages/gunicorn/workers/base.py", line 147, in load_wsgi
    self.wsgi = self.app.wsgi()
                ^^^^^^^^^^^^^^^
  File "/venv/lib/python3.11/site-packages/gunicorn/app/base.py", line 66, in wsgi
    self.callable = self.load()
                    ^^^^^^^^^^^
  File "/venv/lib/python3.11/site-packages/gunicorn/app/wsgiapp.py", line 57, in load
    return self.load_wsgiapp()
           ^^^^^^^^^^^^^^^^^^^
  File "/venv/lib/python3.11/site-packages/gunicorn/app/wsgiapp.py", line 47, in load_wsgiapp
    return util.import_app(self.app_uri)
           ^^^^^^^^^^^^^^^^^^^^^^^^^^^^^
  File "/venv/lib/python3.11/site-packages/gunicorn/util.py", line 370, in import_app
    mod = importlib.import_module(module)
          ^^^^^^^^^^^^^^^^^^^^^^^^^^^^^^^
  File "/usr/lib/python3.11/importlib/__init__.py", line 126, in import_module
    return _bootstrap._gcd_import(name[level:], package, level)
           ^^^^^^^^^^^^^^^^^^^^^^^^^^^^^^^^^^^^^^^^^^^^^^^^^^^^
  File "<frozen importlib._bootstrap>", line 1204, in _gcd_import
  File "<frozen importlib._bootstrap>", line 1176, in _find_and_load
  File "<frozen importlib._bootstrap>", line 1147, in _find_and_load_unlocked
  File "<frozen importlib._bootstrap>", line 690, in _load_unlocked
  File "<frozen importlib._bootstrap_external>", line 940, in exec_module
  File "<frozen importlib._bootstrap>", line 241, in _call_with_frames_removed
  File "/app/driver.py", line 5, in <module>
    from api import create_app
  File "/app/api/__init__.py", line 7, in <module>
    from api.routes.verify_proxy import verify_bp
ModuleNotFoundError: No module named 'api.routes.verify_proxy'; 'api.routes' is not a package
[2025-05-16 17:45:21 +0000] [137] [INFO] Worker exiting (pid: 137)
[2025-05-16 17:45:21 +0000] [138] [ERROR] Exception in worker process
Traceback (most recent call last):
  File "/venv/lib/python3.11/site-packages/gunicorn/arbiter.py", line 608, in spawn_worker
    worker.init_process()
  File "/venv/lib/python3.11/site-packages/gunicorn/workers/ggevent.py", line 146, in init_process
    super().init_process()
  File "/venv/lib/python3.11/site-packages/gunicorn/workers/base.py", line 135, in init_process
    self.load_wsgi()
  File "/venv/lib/python3.11/site-packages/gunicorn/workers/base.py", line 147, in load_wsgi
    self.wsgi = self.app.wsgi()
                ^^^^^^^^^^^^^^^
  File "/venv/lib/python3.11/site-packages/gunicorn/app/base.py", line 66, in wsgi
    self.callable = self.load()
                    ^^^^^^^^^^^
  File "/venv/lib/python3.11/site-packages/gunicorn/app/wsgiapp.py", line 57, in load
    return self.load_wsgiapp()
           ^^^^^^^^^^^^^^^^^^^
  File "/venv/lib/python3.11/site-packages/gunicorn/app/wsgiapp.py", line 47, in load_wsgiapp
    return util.import_app(self.app_uri)
           ^^^^^^^^^^^^^^^^^^^^^^^^^^^^^
  File "/venv/lib/python3.11/site-packages/gunicorn/util.py", line 370, in import_app
    mod = importlib.import_module(module)
          ^^^^^^^^^^^^^^^^^^^^^^^^^^^^^^^
  File "/usr/lib/python3.11/importlib/__init__.py", line 126, in import_module
    return _bootstrap._gcd_import(name[level:], package, level)
           ^^^^^^^^^^^^^^^^^^^^^^^^^^^^^^^^^^^^^^^^^^^^^^^^^^^^
  File "<frozen importlib._bootstrap>", line 1204, in _gcd_import
  File "<frozen importlib._bootstrap>", line 1176, in _find_and_load
  File "<frozen importlib._bootstrap>", line 1147, in _find_and_load_unlocked
  File "<frozen importlib._bootstrap>", line 690, in _load_unlocked
  File "<frozen importlib._bootstrap_external>", line 940, in exec_module
  File "<frozen importlib._bootstrap>", line 241, in _call_with_frames_removed
  File "/app/driver.py", line 5, in <module>
    from api import create_app
  File "/app/api/__init__.py", line 7, in <module>
    from api.routes.verify_proxy import verify_bp
ModuleNotFoundError: No module named 'api.routes.verify_proxy'; 'api.routes' is not a package
[2025-05-16 17:45:21 +0000] [138] [INFO] Worker exiting (pid: 138)
[2025-05-16 17:45:21 +0000] [140] [ERROR] Exception in worker process
Traceback (most recent call last):
  File "/venv/lib/python3.11/site-packages/gunicorn/arbiter.py", line 608, in spawn_worker
    worker.init_process()
  File "/venv/lib/python3.11/site-packages/gunicorn/workers/ggevent.py", line 146, in init_process
    super().init_process()
  File "/venv/lib/python3.11/site-packages/gunicorn/workers/base.py", line 135, in init_process
    self.load_wsgi()
  File "/venv/lib/python3.11/site-packages/gunicorn/workers/base.py", line 147, in load_wsgi
    self.wsgi = self.app.wsgi()
                ^^^^^^^^^^^^^^^
  File "/venv/lib/python3.11/site-packages/gunicorn/app/base.py", line 66, in wsgi
    self.callable = self.load()
                    ^^^^^^^^^^^
  File "/venv/lib/python3.11/site-packages/gunicorn/app/wsgiapp.py", line 57, in load
    return self.load_wsgiapp()
           ^^^^^^^^^^^^^^^^^^^
  File "/venv/lib/python3.11/site-packages/gunicorn/app/wsgiapp.py", line 47, in load_wsgiapp
    return util.import_app(self.app_uri)
           ^^^^^^^^^^^^^^^^^^^^^^^^^^^^^
  File "/venv/lib/python3.11/site-packages/gunicorn/util.py", line 370, in import_app
    mod = importlib.import_module(module)
          ^^^^^^^^^^^^^^^^^^^^^^^^^^^^^^^
  File "/usr/lib/python3.11/importlib/__init__.py", line 126, in import_module
    return _bootstrap._gcd_import(name[level:], package, level)
           ^^^^^^^^^^^^^^^^^^^^^^^^^^^^^^^^^^^^^^^^^^^^^^^^^^^^
  File "<frozen importlib._bootstrap>", line 1204, in _gcd_import
  File "<frozen importlib._bootstrap>", line 1176, in _find_and_load
  File "<frozen importlib._bootstrap>", line 1147, in _find_and_load_unlocked
  File "<frozen importlib._bootstrap>", line 690, in _load_unlocked
  File "<frozen importlib._bootstrap_external>", line 940, in exec_module
  File "<frozen importlib._bootstrap>", line 241, in _call_with_frames_removed
  File "/app/driver.py", line 5, in <module>
    from api import create_app
  File "/app/api/__init__.py", line 7, in <module>
    from api.routes.verify_proxy import verify_bp
ModuleNotFoundError: No module named 'api.routes.verify_proxy'; 'api.routes' is not a package
[2025-05-16 17:45:21 +0000] [140] [INFO] Worker exiting (pid: 140)
[2025-05-16 17:45:21 +0000] [139] [ERROR] Exception in worker process
Traceback (most recent call last):
  File "/venv/lib/python3.11/site-packages/gunicorn/arbiter.py", line 608, in spawn_worker
    worker.init_process()
  File "/venv/lib/python3.11/site-packages/gunicorn/workers/ggevent.py", line 146, in init_process
    super().init_process()
  File "/venv/lib/python3.11/site-packages/gunicorn/workers/base.py", line 135, in init_process
    self.load_wsgi()
  File "/venv/lib/python3.11/site-packages/gunicorn/workers/base.py", line 147, in load_wsgi
    self.wsgi = self.app.wsgi()
                ^^^^^^^^^^^^^^^
  File "/venv/lib/python3.11/site-packages/gunicorn/app/base.py", line 66, in wsgi
    self.callable = self.load()
                    ^^^^^^^^^^^
  File "/venv/lib/python3.11/site-packages/gunicorn/app/wsgiapp.py", line 57, in load
    return self.load_wsgiapp()
           ^^^^^^^^^^^^^^^^^^^
  File "/venv/lib/python3.11/site-packages/gunicorn/app/wsgiapp.py", line 47, in load_wsgiapp
    return util.import_app(self.app_uri)
           ^^^^^^^^^^^^^^^^^^^^^^^^^^^^^
  File "/venv/lib/python3.11/site-packages/gunicorn/util.py", line 370, in import_app
    mod = importlib.import_module(module)
          ^^^^^^^^^^^^^^^^^^^^^^^^^^^^^^^
  File "/usr/lib/python3.11/importlib/__init__.py", line 126, in import_module
    return _bootstrap._gcd_import(name[level:], package, level)
           ^^^^^^^^^^^^^^^^^^^^^^^^^^^^^^^^^^^^^^^^^^^^^^^^^^^^
  File "<frozen importlib._bootstrap>", line 1204, in _gcd_import
  File "<frozen importlib._bootstrap>", line 1176, in _find_and_load
  File "<frozen importlib._bootstrap>", line 1147, in _find_and_load_unlocked
  File "<frozen importlib._bootstrap>", line 690, in _load_unlocked
  File "<frozen importlib._bootstrap_external>", line 940, in exec_module
  File "<frozen importlib._bootstrap>", line 241, in _call_with_frames_removed
  File "/app/driver.py", line 5, in <module>
    from api import create_app
  File "/app/api/__init__.py", line 7, in <module>
    from api.routes.verify_proxy import verify_bp
ModuleNotFoundError: No module named 'api.routes.verify_proxy'; 'api.routes' is not a package
[2025-05-16 17:45:21 +0000] [139] [INFO] Worker exiting (pid: 139)
[2025-05-16 17:45:21 +0000] [141] [ERROR] Exception in worker process
Traceback (most recent call last):
  File "/venv/lib/python3.11/site-packages/gunicorn/arbiter.py", line 608, in spawn_worker
    worker.init_process()
  File "/venv/lib/python3.11/site-packages/gunicorn/workers/ggevent.py", line 146, in init_process
    super().init_process()
  File "/venv/lib/python3.11/site-packages/gunicorn/workers/base.py", line 135, in init_process
    self.load_wsgi()
  File "/venv/lib/python3.11/site-packages/gunicorn/workers/base.py", line 147, in load_wsgi
    self.wsgi = self.app.wsgi()
                ^^^^^^^^^^^^^^^
  File "/venv/lib/python3.11/site-packages/gunicorn/app/base.py", line 66, in wsgi
    self.callable = self.load()
                    ^^^^^^^^^^^
  File "/venv/lib/python3.11/site-packages/gunicorn/app/wsgiapp.py", line 57, in load
    return self.load_wsgiapp()
           ^^^^^^^^^^^^^^^^^^^
  File "/venv/lib/python3.11/site-packages/gunicorn/app/wsgiapp.py", line 47, in load_wsgiapp
    return util.import_app(self.app_uri)
           ^^^^^^^^^^^^^^^^^^^^^^^^^^^^^
  File "/venv/lib/python3.11/site-packages/gunicorn/util.py", line 370, in import_app
    mod = importlib.import_module(module)
          ^^^^^^^^^^^^^^^^^^^^^^^^^^^^^^^
  File "/usr/lib/python3.11/importlib/__init__.py", line 126, in import_module
    return _bootstrap._gcd_import(name[level:], package, level)
           ^^^^^^^^^^^^^^^^^^^^^^^^^^^^^^^^^^^^^^^^^^^^^^^^^^^^
  File "<frozen importlib._bootstrap>", line 1204, in _gcd_import
  File "<frozen importlib._bootstrap>", line 1176, in _find_and_load
  File "<frozen importlib._bootstrap>", line 1147, in _find_and_load_unlocked
  File "<frozen importlib._bootstrap>", line 690, in _load_unlocked
  File "<frozen importlib._bootstrap_external>", line 940, in exec_module
  File "<frozen importlib._bootstrap>", line 241, in _call_with_frames_removed
  File "/app/driver.py", line 5, in <module>
    from api import create_app
  File "/app/api/__init__.py", line 7, in <module>
    from api.routes.verify_proxy import verify_bp
ModuleNotFoundError: No module named 'api.routes.verify_proxy'; 'api.routes' is not a package
[2025-05-16 17:45:21 +0000] [141] [INFO] Worker exiting (pid: 141)
[2025-05-16 17:45:21 +0000] [134] [ERROR] Worker (pid:137) exited with code 3
Traceback (most recent call last):
  File "/venv/lib/python3.11/site-packages/gunicorn/arbiter.py", line 208, in run
    self.sleep()
  File "/venv/lib/python3.11/site-packages/gunicorn/arbiter.py", line 359, in sleep
    ready = select.select([self.PIPE[0]], [], [], 1.0)
            ^^^^^^^^^^^^^^^^^^^^^^^^^^^^^^^^^^^^^^^^^^
  File "/venv/lib/python3.11/site-packages/gunicorn/arbiter.py", line 241, in handle_chld
    self.reap_workers()
  File "/venv/lib/python3.11/site-packages/gunicorn/arbiter.py", line 529, in reap_workers
    raise HaltServer(reason, self.WORKER_BOOT_ERROR)
gunicorn.errors.HaltServer: <HaltServer 'Worker failed to boot.' 3>

During handling of the above exception, another exception occurred:

Traceback (most recent call last):
  File "/venv/bin/gunicorn", line 8, in <module>
    sys.exit(run())
             ^^^^^
  File "/venv/lib/python3.11/site-packages/gunicorn/app/wsgiapp.py", line 66, in run
    WSGIApplication("%(prog)s [OPTIONS] [APP_MODULE]", prog=prog).run()
  File "/venv/lib/python3.11/site-packages/gunicorn/app/base.py", line 235, in run
    super().run()
  File "/venv/lib/python3.11/site-packages/gunicorn/app/base.py", line 71, in run
    Arbiter(self).run()
  File "/venv/lib/python3.11/site-packages/gunicorn/arbiter.py", line 228, in run
    self.halt(reason=inst.reason, exit_status=inst.exit_status)
  File "/venv/lib/python3.11/site-packages/gunicorn/arbiter.py", line 341, in halt
    self.stop()
  File "/venv/lib/python3.11/site-packages/gunicorn/arbiter.py", line 395, in stop
    time.sleep(0.1)
  File "/venv/lib/python3.11/site-packages/gunicorn/arbiter.py", line 241, in handle_chld
    self.reap_workers()
  File "/venv/lib/python3.11/site-packages/gunicorn/arbiter.py", line 529, in reap_workers
    raise HaltServer(reason, self.WORKER_BOOT_ERROR)
gunicorn.errors.HaltServer: <HaltServer 'Worker failed to boot.' 3>
[2025-05-16 17:45:22 +0000] [142] [ERROR] Exception in worker process
Traceback (most recent call last):
  File "/venv/lib/python3.11/site-packages/gunicorn/arbiter.py", line 608, in spawn_worker
    worker.init_process()
  File "/venv/lib/python3.11/site-packages/gunicorn/workers/ggevent.py", line 146, in init_process
    super().init_process()
  File "/venv/lib/python3.11/site-packages/gunicorn/workers/base.py", line 135, in init_process
    self.load_wsgi()
  File "/venv/lib/python3.11/site-packages/gunicorn/workers/base.py", line 147, in load_wsgi
    self.wsgi = self.app.wsgi()
                ^^^^^^^^^^^^^^^
  File "/venv/lib/python3.11/site-packages/gunicorn/app/base.py", line 66, in wsgi
    self.callable = self.load()
                    ^^^^^^^^^^^
  File "/venv/lib/python3.11/site-packages/gunicorn/app/wsgiapp.py", line 57, in load
    return self.load_wsgiapp()
           ^^^^^^^^^^^^^^^^^^^
  File "/venv/lib/python3.11/site-packages/gunicorn/app/wsgiapp.py", line 47, in load_wsgiapp
    return util.import_app(self.app_uri)
           ^^^^^^^^^^^^^^^^^^^^^^^^^^^^^
  File "/venv/lib/python3.11/site-packages/gunicorn/util.py", line 370, in import_app
    mod = importlib.import_module(module)
          ^^^^^^^^^^^^^^^^^^^^^^^^^^^^^^^
  File "/usr/lib/python3.11/importlib/__init__.py", line 126, in import_module
    return _bootstrap._gcd_import(name[level:], package, level)
           ^^^^^^^^^^^^^^^^^^^^^^^^^^^^^^^^^^^^^^^^^^^^^^^^^^^^
  File "<frozen importlib._bootstrap>", line 1204, in _gcd_import
  File "<frozen importlib._bootstrap>", line 1176, in _find_and_load
  File "<frozen importlib._bootstrap>", line 1147, in _find_and_load_unlocked
  File "<frozen importlib._bootstrap>", line 690, in _load_unlocked
  File "<frozen importlib._bootstrap_external>", line 940, in exec_module
  File "<frozen importlib._bootstrap>", line 241, in _call_with_frames_removed
  File "/app/driver.py", line 5, in <module>
    from api import create_app
  File "/app/api/__init__.py", line 7, in <module>
    from api.routes.verify_proxy import verify_bp
ModuleNotFoundError: No module named 'api.routes.verify_proxy'; 'api.routes' is not a package
[2025-05-16 17:45:22 +0000] [142] [INFO] Worker exiting (pid: 142)
[2025-05-16 17:45:22 +0000] [143] [ERROR] Exception in worker process
Traceback (most recent call last):
  File "/venv/lib/python3.11/site-packages/gunicorn/arbiter.py", line 608, in spawn_worker
    worker.init_process()
  File "/venv/lib/python3.11/site-packages/gunicorn/workers/ggevent.py", line 146, in init_process
    super().init_process()
  File "/venv/lib/python3.11/site-packages/gunicorn/workers/base.py", line 135, in init_process
    self.load_wsgi()
  File "/venv/lib/python3.11/site-packages/gunicorn/workers/base.py", line 147, in load_wsgi
    self.wsgi = self.app.wsgi()
                ^^^^^^^^^^^^^^^
  File "/venv/lib/python3.11/site-packages/gunicorn/app/base.py", line 66, in wsgi
    self.callable = self.load()
                    ^^^^^^^^^^^
  File "/venv/lib/python3.11/site-packages/gunicorn/app/wsgiapp.py", line 57, in load
    return self.load_wsgiapp()
           ^^^^^^^^^^^^^^^^^^^
  File "/venv/lib/python3.11/site-packages/gunicorn/app/wsgiapp.py", line 47, in load_wsgiapp
    return util.import_app(self.app_uri)
           ^^^^^^^^^^^^^^^^^^^^^^^^^^^^^
  File "/venv/lib/python3.11/site-packages/gunicorn/util.py", line 370, in import_app
    mod = importlib.import_module(module)
          ^^^^^^^^^^^^^^^^^^^^^^^^^^^^^^^
  File "/usr/lib/python3.11/importlib/__init__.py", line 126, in import_module
    return _bootstrap._gcd_import(name[level:], package, level)
           ^^^^^^^^^^^^^^^^^^^^^^^^^^^^^^^^^^^^^^^^^^^^^^^^^^^^
  File "<frozen importlib._bootstrap>", line 1204, in _gcd_import
  File "<frozen importlib._bootstrap>", line 1176, in _find_and_load
  File "<frozen importlib._bootstrap>", line 1147, in _find_and_load_unlocked
  File "<frozen importlib._bootstrap>", line 690, in _load_unlocked
  File "<frozen importlib._bootstrap_external>", line 940, in exec_module
  File "<frozen importlib._bootstrap>", line 241, in _call_with_frames_removed
  File "/app/driver.py", line 5, in <module>
    from api import create_app
  File "/app/api/__init__.py", line 7, in <module>
    from api.routes.verify_proxy import verify_bp
ModuleNotFoundError: No module named 'api.routes.verify_proxy'; 'api.routes' is not a package
-e 
===== ./database.log =====

[2025-05-16 17:45:04,999] INFO in driver: Initializing database tables...
[2025-05-16 17:45:05,054] INFO in driver: âœ… Tables created.
[2025-05-16 17:45:06,287] INFO in driver: [driver] Starting Flask app on http://0.0.0.0:5003
[2025-05-16 17:45:06,292] INFO in driver: static: /static/<path:filename> [HEAD,GET,OPTIONS]
[2025-05-16 17:45:06,292] INFO in driver: main.get_secret: /get_secret/<eth_address> [HEAD,GET,OPTIONS]
[2025-05-16 17:45:06,292] INFO in driver: main.retrieve_magnet_urls: /get_magnet_urls/<eth_address> [HEAD,GET,OPTIONS]
[2025-05-16 17:45:06,292] INFO in driver: main.generate_and_store_secret: /generate_secret [POST,OPTIONS]
[2025-05-16 17:45:06,292] INFO in driver: main.get_rtmp_url: /get_rtmp_url/<eth_address> [HEAD,GET,OPTIONS]
[2025-05-16 17:45:06,292] INFO in driver: main.store_magnet_url_route: /store_magnet_url [POST,OPTIONS]
[2025-05-16 17:45:06,292] INFO in driver: main.clear_magnet_urls_route: /clear_magnet_urls/<eth_address> [DELETE,OPTIONS]
[2025-05-16 17:45:06,292] INFO in driver: main.store_streamer_info: /store_streamer_info [POST,OPTIONS]
[2025-05-16 17:45:06,292] INFO in driver: main.get_streamer_ip: /get_streamer_eth_address/<ip_address> [HEAD,GET,OPTIONS]
[2025-05-16 17:45:06,292] INFO in driver: main.verify_secret_fun: /verify_secret [POST,OPTIONS]
[2025-05-16 17:45:06,292] INFO in driver: main.create_group: /create_group [POST,OPTIONS]
[2025-05-16 17:45:06,293] INFO in driver: main.add_file_to_group: /add_file_to_group [POST,OPTIONS]
[2025-05-16 17:45:06,293] INFO in driver: main.update_file_metadata: /update_file_metadata [POST,OPTIONS]
[2025-05-16 17:45:06,293] INFO in driver: main.get_group_files: /get_group_files/<int:group_id> [HEAD,GET,OPTIONS]
[2025-05-16 17:45:06,293] INFO in driver: main.list_snapshots: /list_snapshots [HEAD,GET,OPTIONS]
[2025-05-16 17:45:06,332] INFO in _internal: [31m[1mWARNING: This is a development server. Do not use it in a production deployment. Use a production WSGI server instead.[0m
 * Running on all addresses (0.0.0.0)
 * Running on http://127.0.0.1:5003
 * Running on http://172.19.0.2:5003
[2025-05-16 17:45:06,335] INFO in _internal: [33mPress CTRL+C to quit[0m
[2025-05-16 17:45:06,338] INFO in _internal:  * Restarting with stat
[2025-05-16 17:45:07,260] INFO in driver: [driver] Starting Flask app on http://0.0.0.0:5003
[2025-05-16 17:45:07,264] INFO in driver: static: /static/<path:filename> [OPTIONS,HEAD,GET]
[2025-05-16 17:45:07,264] INFO in driver: main.get_secret: /get_secret/<eth_address> [OPTIONS,HEAD,GET]
[2025-05-16 17:45:07,265] INFO in driver: main.retrieve_magnet_urls: /get_magnet_urls/<eth_address> [OPTIONS,HEAD,GET]
[2025-05-16 17:45:07,267] INFO in driver: main.generate_and_store_secret: /generate_secret [OPTIONS,POST]
[2025-05-16 17:45:07,271] INFO in driver: main.get_rtmp_url: /get_rtmp_url/<eth_address> [OPTIONS,HEAD,GET]
[2025-05-16 17:45:07,271] INFO in driver: main.store_magnet_url_route: /store_magnet_url [OPTIONS,POST]
[2025-05-16 17:45:07,271] INFO in driver: main.clear_magnet_urls_route: /clear_magnet_urls/<eth_address> [OPTIONS,DELETE]
[2025-05-16 17:45:07,271] INFO in driver: main.store_streamer_info: /store_streamer_info [OPTIONS,POST]
[2025-05-16 17:45:07,272] INFO in driver: main.get_streamer_ip: /get_streamer_eth_address/<ip_address> [OPTIONS,HEAD,GET]
[2025-05-16 17:45:07,272] INFO in driver: main.verify_secret_fun: /verify_secret [OPTIONS,POST]
[2025-05-16 17:45:07,272] INFO in driver: main.create_group: /create_group [OPTIONS,POST]
[2025-05-16 17:45:07,272] INFO in driver: main.add_file_to_group: /add_file_to_group [OPTIONS,POST]
[2025-05-16 17:45:07,272] INFO in driver: main.update_file_metadata: /update_file_metadata [OPTIONS,POST]
[2025-05-16 17:45:07,272] INFO in driver: main.get_group_files: /get_group_files/<int:group_id> [OPTIONS,HEAD,GET]
[2025-05-16 17:45:07,272] INFO in driver: main.list_snapshots: /list_snapshots [OPTIONS,HEAD,GET]
[2025-05-16 17:45:07,302] WARNING in _internal:  * Debugger is active!
[2025-05-16 17:45:07,307] INFO in _internal:  * Debugger PIN: 114-130-556
[2025-05-16 17:45:07,784] INFO in _internal: 172.19.0.6 - - [16/May/2025 17:45:07] "[35m[1mGET /get_magnet_urls/0xtest HTTP/1.1[0m" 500 -
[2025-05-16 17:45:16,369] INFO in _internal: 172.19.0.4 - - [16/May/2025 17:45:16] "POST /store_magnet_url HTTP/1.1" 200 -
-e 
===== ./gunicorn.out.log =====

-e 
===== ./verifier.out.log =====

